Workbook
Name Б3: #REF!

Sheet ДЛЯ КАЮ
A1: Нир и Тр | D1: Карантин | H1: Реестр План/Факт | J1: Сортность | N1: ТМЦ
A2: Период | B2: Нир | C2: Тр | D2: Период | E2: Nзадачи | F2: Тср (ч) | G2: Т48+ | H2: Период | I2: Среднее общее | J2: Период | K2: Сырье,% | L2: Промежуточный контроль,% | M2: Готовая ткань,% | N2: Период | O2: Отклонение (дни) среднее | P2: %
A3: =WEEKNUM(TODAY(),21) -> 12 | D3: =WEEKNUM(TODAY(),21) -> 12 | H3: =WEEKNUM(TODAY(),21) -> 12 | I3: =IFERROR(INDEX(Реестр_План_Факт!AO373:AO425,MATCH(A3,Реестр_План_Факт!A373:A425,0)),0) -> 1.0601021 | J3: =WEEKNUM(TODAY(),21) -> 12 | K3: =IFERROR(INDEX(Сортность!H2:H54,MATCH($A3,Сортность!$G2:$G54,0)),0) -> 99.64 | L3: =IFERROR(INDEX(Сортность!I2:I54,MATCH($A3,Сортность!$G2:$G54,0)),0) -> 98.335 | M3: =IFERROR(INDEX(Сортность!J2:J54,MATCH($A3,Сортность!$G2:$G54,0)),0) -> 98.47 | N3: =WEEKNUM(TODAY(),21) -> 12
A4: Март | B4: =IFERROR(INDEX(НИР_ТР!B2:B13,MATCH(A4,НИР_ТР!A2:A13,0)),0) -> 0 | C4: =IFERROR(INDEX(НИР_ТР!C2:C13,MATCH(A4,НИР_ТР!A2:A13,0)),0) -> 0 | D4: Март | E4: =COUNTIFS(Карантин!D:D,"<>",Карантин!G:G,D4&" "&D5) -> 13 | F4: =IFERROR(INT(AVERAGEIFS(Карантин!E:E,Карантин!G:G,D4&" "&D5))&" час "&ROUND((AVERAGEIFS(Карантин!E:E,Карантин!G:G,D4&" "&D5)-INT(AVERAGEIFS(Карантин!E:E,Карантин!G:G,D4&" "&D5)))*60,0)&" минут",0) -> 1 час 31 минут | G4: =COUNTIFS(Карантин!E:E,">48",Карантин!G:G,D4&" "&D5) -> 0 | H4: Март | I4: =IFERROR(INDEX(Реестр_План_Факт!AO427:AO438,MATCH(H4,Реестр_План_Факт!A427:A438,0)),0) -> 1.0037129 | J4: Март | K4: =IFERROR(INDEX(Сортность!L2:L13,MATCH($J4,Сортность!$K2:$K13,0)),0) -> 98.679286 | L4: =IFERROR(INDEX(Сортность!M2:M13,MATCH($J4,Сортность!$K2:$K13,0)),0) -> 93.616429 | M4: =IFERROR(INDEX(Сортность!N2:N13,MATCH($J4,Сортность!$K2:$K13,0)),0) -> 98.235 | N4: Март | O4: =IFERROR(AVERAGEIFS(ВЭД_ТМЦ!L:L,ВЭД_ТМЦ!N:N,N4&" "&N5),0) -> -9.4545455 | P4: =IFERROR(AVERAGEIFS(ВЭД_ТМЦ!$M:$M,ВЭД_ТМЦ!$J:$J,">="&DATE(YEAR(TODAY()),MONTH(TODAY()),1),ВЭД_ТМЦ!$J:$J,"<"&EOMONTH(TODAY(),0)+1),0) -> -0.073851975
A5: =YEAR(TODAY()) -> 2026 | B5: =НИР_ТР!B14 -> 0 | C5: =НИР_ТР!C14 -> 0 | D5: =YEAR(TODAY()) -> 2026 | E5: =COUNTIFS(Карантин!D:D,"<>",Карантин!G:G,"*"&A5) -> 14 | F5: =IFERROR(INT(AVERAGEIFS(Карантин!E:E,Карантин!G:G,"*"&A5))&" час "&ROUND((AVERAGEIFS(Карантин!E:E,Карантин!G:G,"*"&A5)-INT(AVERAGEIFS(Карантин!E:E,Карантин!G:G,"*"&A5)))*60,0)&" минут","") -> 1 час 25 минут | G5: =COUNTIFS(Карантин!E:E,">48",Карантин!G:G,"*"&D5) -> 0 | H5: =YEAR(TODAY()) -> 2026 | I5: =Реестр_План_Факт!AO440 -> 1.0037129 | J5: =YEAR(TODAY()) -> 2026 | K5: =Сортность!L14 -> 98.679286 | L5: =Сортность!M14 -> 93.616429 | M5: =Сортность!N14 -> 98.6475 | N5: =YEAR(TODAY()) -> 2026 | O5: =IFERROR(SUMIFS(ВЭД_ТМЦ!$L:$L,ВЭД_ТМЦ!$J:$J,">="&DATE(YEAR(TODAY()),1,1),ВЭД_ТМЦ!$J:$J,"<"&TODAY()+1),0) -> -108 | P5: =IFERROR(SUMPRODUCT((ВЭД_ТМЦ!$J$2:$J$5000>=DATE(YEAR(TODAY()),1,1))*(ВЭД_ТМЦ!$J$2:$J$5000<TODAY()+1)*(ВЭД_ТМЦ!$I$2:$I$5000<>"")*(ВЭД_ТМЦ!$K$2:$K$5000<>"")*(ВЭД_ТМЦ!$I$2:$I$5000>ВЭД_ТМЦ!$K$2:$K$5000)*(ВЭД_ТМЦ!$J$2:$J$5000-ВЭД_ТМЦ!$I$2:$I$5000))/SUMPRODUCT((ВЭД_ТМЦ!$J$2:$J$5000>=DATE(YEAR(TODAY()),1,1))*(ВЭД_ТМЦ!$J$2:$J$5000<TODAY()+1)*(ВЭД_ТМЦ!$I$2:$I$5000<>"")*(ВЭД_ТМЦ!$K$2:$K$5000<>"")*(ВЭД_ТМЦ!$I$2:$I$5000>ВЭД_ТМЦ!$K$2:$K$5000)*(ВЭД_ТМЦ!$I$2:$I$5000-ВЭД_ТМЦ!$K$2:$K$5000)),0) -> -0.064864865
A6: Чистота
A7: Период | B7: ОТК | C7: Б2 | D7: Б3 | E7: Б4 | F7: Крашение | G7: СШМ | H7: Лабдип | I7: Мембрана | J7: Ворсование | K7: Тумблирование | L7: Вязание | M7: Ленты | N7: Склад ГП | O7: Склад сырья | P7: Лаборатория | Q7: Печать(ЦП+ВП) | R7: Техническое обслуживание чистоты
A8: =WEEKNUM(TODAY(),21) -> 12
A9: Февраль | B9: =IFERROR(INDEX(Чистота_Порядок!B2:B13,MATCH($A9,Чистота_Порядок!$A2:$A13,0)),0) -> 4.4 | C9: =IFERROR(INDEX(Чистота_Порядок!C2:C13,MATCH($A9,Чистота_Порядок!$A2:$A13,0)),0) -> 4.3 | D9: =IFERROR(INDEX(Чистота_Порядок!D2:D13,MATCH($A9,Чистота_Порядок!$A2:$A13,0)),0) -> 4.2 | E9: =IFERROR(INDEX(Чистота_Порядок!E2:E13,MATCH($A9,Чистота_Порядок!$A2:$A13,0)),0) -> 4.3 | F9: =IFERROR(INDEX(Чистота_Порядок!F2:F13,MATCH($A9,Чистота_Порядок!$A2:$A13,0)),0) -> 4.3 | G9: =IFERROR(INDEX(Чистота_Порядок!G2:G13,MATCH($A9,Чистота_Порядок!$A2:$A13,0)),0) -> 4.3 | H9: =IFERROR(INDEX(Чистота_Порядок!H2:H13,MATCH($A9,Чистота_Порядок!$A2:$A13,0)),0) -> 4.3 | I9: =IFERROR(INDEX(Чистота_Порядок!I2:I13,MATCH($A9,Чистота_Порядок!$A2:$A13,0)),0) -> 4.4 | ... R9: =IFERROR(INDEX(Чистота_Порядок!R2:R13,MATCH($A9,Чистота_Порядок!$A2:$A13,0)),0) -> 5
A10: =YEAR(TODAY()) -> 2026

Sheet Поступления_Тех
A1: month_date | B1: plan_k_rub | C1: fact_k_rub | D1: source_sheet | E1: source_row | F1: Месяц
A2: =DATE(YEAR(Деньги_Отгрузки!E15),MONTH(Деньги_Отгрузки!E15),1) -> 44197 | B2: =Деньги_Отгрузки!E16 -> 150000 | C2: =Деньги_Отгрузки!E17 -> 37242.239 | D2: Деньги_Отгрузки | E2: 15 | F2: Январь
A3: =DATE(YEAR(Деньги_Отгрузки!F15),MONTH(Деньги_Отгрузки!F15),1) -> 44228 | B3: =Деньги_Отгрузки!F16 -> 150000 | C3: =Деньги_Отгрузки!F17 -> 175897.67 | D3: Деньги_Отгрузки | E3: 15 | F3: Февраль
A4: =DATE(YEAR(Деньги_Отгрузки!G15),MONTH(Деньги_Отгрузки!G15),1) -> 44256 | B4: =Деньги_Отгрузки!G16 -> 150000 | C4: =Деньги_Отгрузки!G17 -> 0 | D4: Деньги_Отгрузки | E4: 15 | F4: Март
A5: =DATE(YEAR(Деньги_Отгрузки!H15),MONTH(Деньги_Отгрузки!H15),1) -> 44287 | B5: =Деньги_Отгрузки!H16 -> 150000 | C5: =Деньги_Отгрузки!H17 -> 0 | D5: Деньги_Отгрузки | E5: 15 | F5: Апрель
A6: =DATE(YEAR(Деньги_Отгрузки!I15),MONTH(Деньги_Отгрузки!I15),1) -> 44317 | B6: =Деньги_Отгрузки!I16 -> 150000 | C6: =Деньги_Отгрузки!I17 -> 0 | D6: Деньги_Отгрузки | E6: 15 | F6: Май
A7: =DATE(YEAR(Деньги_Отгрузки!J15),MONTH(Деньги_Отгрузки!J15),1) -> 44348 | B7: =Деньги_Отгрузки!J16 -> 150000 | C7: =Деньги_Отгрузки!J17 -> 0 | D7: Деньги_Отгрузки | E7: 15 | F7: Июнь
A8: =DATE(YEAR(Деньги_Отгрузки!K15),MONTH(Деньги_Отгрузки!K15),1) -> 44378 | B8: =Деньги_Отгрузки!K16 -> 150000 | C8: =Деньги_Отгрузки!K17 -> 0 | D8: Деньги_Отгрузки | E8: 15 | F8: Июль
A9: =DATE(YEAR(Деньги_Отгрузки!L15),MONTH(Деньги_Отгрузки!L15),1) -> 44409 | B9: =Деньги_Отгрузки!L16 -> 150000 | C9: =Деньги_Отгрузки!L17 -> 0 | D9: Деньги_Отгрузки | E9: 15 | F9: Август
A10: =DATE(YEAR(Деньги_Отгрузки!M15),MONTH(Деньги_Отгрузки!M15),1) -> 44440 | B10: =Деньги_Отгрузки!M16 -> 150000 | C10: =Деньги_Отгрузки!M17 -> 0 | D10: Деньги_Отгрузки | E10: 15 | F10: Сентябрь
A11: =DATE(YEAR(Деньги_Отгрузки!N15),MONTH(Деньги_Отгрузки!N15),1) -> 44470 | B11: =Деньги_Отгрузки!N16 -> 150000 | C11: =Деньги_Отгрузки!N17 -> 0 | D11: Деньги_Отгрузки | E11: 15 | F11: Октябрь
A12: =DATE(YEAR(Деньги_Отгрузки!O15),MONTH(Деньги_Отгрузки!O15),1) -> 44501 | B12: =Деньги_Отгрузки!O16 -> 150000 | C12: =Деньги_Отгрузки!O17 -> 0 | D12: Деньги_Отгрузки | E12: 15 | F12: Ноябрь
A13: =DATE(YEAR(Деньги_Отгрузки!P15),MONTH(Деньги_Отгрузки!P15),1) -> 44531 | B13: =Деньги_Отгрузки!P16 -> 150000 | C13: =Деньги_Отгрузки!P17 -> 0 | D13: Деньги_Отгрузки | E13: 15 | F13: Декабрь

Sheet Отгрузки_Тех
A1: month_date | B1: shipment_volume_m | C1: shipment_value_k_rub | D1: source_sheet | E1: source_row | F1: Месяц
A2: =DATE(YEAR(Деньги_Отгрузки!E6),MONTH(Деньги_Отгрузки!E6),1) -> 44197 | B2: =Деньги_Отгрузки!E7 -> 155280.55 | C2: =Деньги_Отгрузки!E8 -> 49909.246 | D2: Деньги_Отгрузки | E2: 6 | F2: Январь
A3: =DATE(YEAR(Деньги_Отгрузки!F6),MONTH(Деньги_Отгрузки!F6),1) -> 44228 | B3: =Деньги_Отгрузки!F7 -> 61826.05 | C3: =Деньги_Отгрузки!F8 -> 44395.135 | D3: Деньги_Отгрузки | E3: 6 | F3: Февраль
A4: =DATE(YEAR(Деньги_Отгрузки!G6),MONTH(Деньги_Отгрузки!G6),1) -> 44256 | B4: =Деньги_Отгрузки!G7 -> 0 | C4: =Деньги_Отгрузки!G8 -> 0 | D4: Деньги_Отгрузки | E4: 6 | F4: Март
A5: =DATE(YEAR(Деньги_Отгрузки!H6),MONTH(Деньги_Отгрузки!H6),1) -> 44287 | B5: =Деньги_Отгрузки!H7 -> 0 | C5: =Деньги_Отгрузки!H8 -> 0 | D5: Деньги_Отгрузки | E5: 6 | F5: Апрель
A6: =DATE(YEAR(Деньги_Отгрузки!I6),MONTH(Деньги_Отгрузки!I6),1) -> 44317 | B6: =Деньги_Отгрузки!I7 -> 0 | C6: =Деньги_Отгрузки!I8 -> 0 | D6: Деньги_Отгрузки | E6: 6 | F6: Май
A7: =DATE(YEAR(Деньги_Отгрузки!J6),MONTH(Деньги_Отгрузки!J6),1) -> 44348 | B7: =Деньги_Отгрузки!J7 -> 0 | C7: =Деньги_Отгрузки!J8 -> 0 | D7: Деньги_Отгрузки | E7: 6 | F7: Июнь
A8: =DATE(YEAR(Деньги_Отгрузки!K6),MONTH(Деньги_Отгрузки!K6),1) -> 44378 | B8: =Деньги_Отгрузки!K7 -> 0 | C8: =Деньги_Отгрузки!K8 -> 0 | D8: Деньги_Отгрузки | E8: 6 | F8: Июль
A9: =DATE(YEAR(Деньги_Отгрузки!L6),MONTH(Деньги_Отгрузки!L6),1) -> 44409 | B9: =Деньги_Отгрузки!L7 -> 0 | C9: =Деньги_Отгрузки!L8 -> 0 | D9: Деньги_Отгрузки | E9: 6 | F9: Август
A10: =DATE(YEAR(Деньги_Отгрузки!M6),MONTH(Деньги_Отгрузки!M6),1) -> 44440 | B10: =Деньги_Отгрузки!M7 -> 0 | C10: =Деньги_Отгрузки!M8 -> 0 | D10: Деньги_Отгрузки | E10: 6 | F10: Сентябрь
A11: =DATE(YEAR(Деньги_Отгрузки!N6),MONTH(Деньги_Отгрузки!N6),1) -> 44470 | B11: =Деньги_Отгрузки!N7 -> 0 | C11: =Деньги_Отгрузки!N8 -> 0 | D11: Деньги_Отгрузки | E11: 6 | F11: Октябрь
A12: =DATE(YEAR(Деньги_Отгрузки!O6),MONTH(Деньги_Отгрузки!O6),1) -> 44501 | B12: =Деньги_Отгрузки!O7 -> 0 | C12: =Деньги_Отгрузки!O8 -> 0 | D12: Деньги_Отгрузки | E12: 6 | F12: Ноябрь
A13: =DATE(YEAR(Деньги_Отгрузки!P6),MONTH(Деньги_Отгрузки!P6),1) -> 44531 | B13: =Деньги_Отгрузки!P7 -> 0 | C13: =Деньги_Отгрузки!P8 -> 0 | D13: Деньги_Отгрузки | E13: 6 | F13: Декабрь

Sheet Деньги_Отгрузки
C2: Объем и стоимость отгружаемых товаров
C4: Отгружено, тыс. руб.
E6: 44197 | F6: 44228 | G6: 44256 | H6: 44287 | I6: 44317 | J6: 44348 | K6: 44378 | L6: 44409 | M6: 44440 | N6: 44470 | O6: 44501 | P6: 44531
C7: Объем факт, метры погонные | E7: 155280.55 | F7: 61826.05
C8: Стоимость факт, тыс. руб. | E8: 49909.246 | F8: 44395.135
C11: Поступление денежных средств
C13: Выручка тыс. руб.
E15: 44197 | F15: 44228 | G15: 44256 | H15: 44287 | I15: 44317 | J15: 44348 | K15: 44378 | L15: 44409 | M15: 44440 | N15: 44470 | O15: 44501 | P15: 44531
C16: План, тыс. руб. | E16: 150000 | F16: 150000 | G16: 150000 | H16: 150000 | I16: 150000 | J16: 150000 | K16: 150000 | L16: 150000 | M16: 150000 | N16: 150000 | O16: 150000 | P16: 150000
C17: Факт, тыс. руб. | E17: 37242.239 | F17: 175897.67

Sheet НИР_ТР
A1: Статус"закрыто" | B1: НИР | C1: ТР
A2: Январь | B2: 0 | C2: 0
A3: Февраль | B3: 0 | C3: 0
A4: Март
A5: Апрель
A6: Май
A7: Июнь
A8: Июль
A9: Август
A10: Сентябрь
A11: Октябрь
A12: Ноябрь
A13: Декабрь
A14: 2026 | B14: =SUM(B2:B13) -> 0 | C14: =SUM(C2:C13) -> 0

Sheet Реестр_План_Факт
A1: Дата | B1: Неделя | C1: Месяц | D1: План Б2.Б3,Б4, м.пог. | E1: Факт Б2.Б3,Б4, м.пог. | F1: % выполнения Б2.Б3,Б4 | G1: План цветная печать, м.пог. | H1: Факт цветная печать, м.пог. | I1: % выполнения цветная печать | J1: План валовая печать,м.пог. | K1: Факт валовая печать,м.пог. | L1: % выполнения валовая печать | M1: План Джиггер1,2 ;Джет, циклы | N1: Факт Джиггер 1,2;Джет,циклы | O1: % выполнения Джиггер 1,2;Джет,циклы | P1: План Жгут циклы | Q1: Факт Жгут циклы | R1: % выполнения Жгут циклы | S1: План СШМ, м.пог. | T1: Факт СШМ, м.пог. | U1: % выполнения СШМ | V1: План СШМ,кг(флис) | W1: Факт СШМ,кг(флис) | X1: % выполнения СШМ,кг(флис) | Y1: План мембрана, м.пог. | Z1: Факт мембрана, м.пог. | AA1: % выполнения мембрана | AB1: План ленты(1-й слой), м.пог. | AC1: Факт ленты(1-й слой), м.пог. | AD1: % выполнения ленты(1-й слой) | AE1: Ленты(резка), м.пог. 1 | AF1: Ленты(резка), м.пог. 2 | AG1: % выполнения Ленты(резка) | AH1: План флис(вязание) ,кг | AI1: Факт Флис(вязание),кг | AJ1: % выполнения Флис(вязание) | AK1: План флис(ворсование),кг. | AL1: Факт флис(ворсование),кг. | AM1: % выполнения флис(ворсование) | AN1: План флис(тумблировние),кг | AO1: Факт флис(тумблировние),кг | AP1: % выполнения флис(тумблировние),кг
A2: 46023 | B2: =ROUNDUP((A2-DATE(YEAR(A2),1,1)+WEEKDAY(DATE(YEAR(A2),1,1),2))/7,0) -> 1 | C2: =MONTH(A2) -> 1 | F2: =IFERROR(E2/D2,"") | L2: =IFERROR(K2/J2,"") | O2: =IFERROR(N2/M2,"") | R2: =IFERROR(Q2/P2,"") | U2: =IFERROR(T2/S2,"") | X2: =IFERROR(W2/V2,"") | AA2: =IFERROR(Z2/Y2,"") | AD2: =IFERROR(AC2/AB2,"") | AG2: =IFERROR(AF2/AE2,"") | AJ2: =IFERROR(AI2/AH2,"") | AM2: =IFERROR(AL2/AK2,"") | AP2: =IFERROR(AO2/AN2,"")
A3: 46024 | B3: =ROUNDUP((A3-DATE(YEAR(A3),1,1)+WEEKDAY(DATE(YEAR(A3),1,1),2))/7,0) -> 1 | C3: =MONTH(A3) -> 1 | F3: =IFERROR(E3/D3,"") | I3: =IFERROR(H3/G3,"") | L3: =IFERROR(K3/J3,"") | O3: =IFERROR(N3/M3,"") | R3: =IFERROR(Q3/P3,"") | U3: =IFERROR(T3/S3,"") | X3: =IFERROR(W3/V3,"") | AA3: =IFERROR(Z3/Y3,"") | AD3: =IFERROR(AC3/AB3,"") | AG3: =IFERROR(AF3/AE3,"") | AJ3: =IFERROR(AI3/AH3,"") | AM3: =IFERROR(AL3/AK3,"") | AP3: =IFERROR(AO3/AN3,"")
A4: 46025 | B4: =ROUNDUP((A4-DATE(YEAR(A4),1,1)+WEEKDAY(DATE(YEAR(A4),1,1),2))/7,0) -> 1 | C4: =MONTH(A4) -> 1 | F4: =IFERROR(E4/D4,"") | I4: =IFERROR(H4/G4,"") | L4: =IFERROR(K4/J4,"") | O4: =IFERROR(N4/M4,"") | R4: =IFERROR(Q4/P4,"") | U4: =IFERROR(T4/S4,"") | X4: =IFERROR(W4/V4,"") | AA4: =IFERROR(Z4/Y4,"") | AD4: =IFERROR(AC4/AB4,"") | AG4: =IFERROR(AF4/AE4,"") | AJ4: =IFERROR(AI4/AH4,"") | AM4: =IFERROR(AL4/AK4,"") | AP4: =IFERROR(AO4/AN4,"")
A5: 46026 | B5: =ROUNDUP((A5-DATE(YEAR(A5),1,1)+WEEKDAY(DATE(YEAR(A5),1,1),2))/7,0) -> 1 | C5: =MONTH(A5) -> 1 | F5: =IFERROR(E5/D5,"") | I5: =IFERROR(H5/G5,"") | L5: =IFERROR(K5/J5,"") | O5: =IFERROR(N5/M5,"") | R5: =IFERROR(Q5/P5,"") | U5: =IFERROR(T5/S5,"") | X5: =IFERROR(W5/V5,"") | AA5: =IFERROR(Z5/Y5,"") | AD5: =IFERROR(AC5/AB5,"") | AG5: =IFERROR(AF5/AE5,"") | AJ5: =IFERROR(AI5/AH5,"") | AM5: =IFERROR(AL5/AK5,"") | AP5: =IFERROR(AO5/AN5,"")
A6: 46027 | B6: =ROUNDUP((A6-DATE(YEAR(A6),1,1)+WEEKDAY(DATE(YEAR(A6),1,1),2))/7,0) -> 2 | C6: =MONTH(A6) -> 1 | F6: =IFERROR(E6/D6,"") | I6: =IFERROR(H6/G6,"") | L6: =IFERROR(K6/J6,"") | O6: =IFERROR(N6/M6,"") | R6: =IFERROR(Q6/P6,"") | U6: =IFERROR(T6/S6,"") | X6: =IFERROR(W6/V6,"") | AA6: =IFERROR(Z6/Y6,"") | AD6: =IFERROR(AC6/AB6,"") | AG6: =IFERROR(AF6/AE6,"") | AJ6: =IFERROR(AI6/AH6,"") | AM6: =IFERROR(AL6/AK6,"") | AP6: =IFERROR(AO6/AN6,"")
A7: 46028 | B7: =ROUNDUP((A7-DATE(YEAR(A7),1,1)+WEEKDAY(DATE(YEAR(A7),1,1),2))/7,0) -> 2 | C7: =MONTH(A7) -> 1 | F7: =IFERROR(E7/D7,"") | I7: =IFERROR(H7/G7,"") | L7: =IFERROR(K7/J7,"") | O7: =IFERROR(N7/M7,"") | R7: =IFERROR(Q7/P7,"") | U7: =IFERROR(T7/S7,"") | X7: =IFERROR(W7/V7,"") | AA7: =IFERROR(Z7/Y7,"") | AD7: =IFERROR(AC7/AB7,"") | AG7: =IFERROR(AF7/AE7,"") | AJ7: =IFERROR(AI7/AH7,"") | AM7: =IFERROR(AL7/AK7,"") | AP7: =IFERROR(AO7/AN7,"")
A8: 46029 | B8: =ROUNDUP((A8-DATE(YEAR(A8),1,1)+WEEKDAY(DATE(YEAR(A8),1,1),2))/7,0) -> 2 | C8: =MONTH(A8) -> 1 | F8: =IFERROR(E8/D8,"") | I8: =IFERROR(H8/G8,"") | L8: =IFERROR(K8/J8,"") | O8: =IFERROR(N8/M8,"") | R8: =IFERROR(Q8/P8,"") | U8: =IFERROR(T8/S8,"") | X8: =IFERROR(W8/V8,"") | AA8: =IFERROR(Z8/Y8,"") | AD8: =IFERROR(AC8/AB8,"") | AG8: =IFERROR(AF8/AE8,"") | AJ8: =IFERROR(AI8/AH8,"") | AM8: =IFERROR(AL8/AK8,"") | AP8: =IFERROR(AO8/AN8,"")
A9: 46030 | B9: =ROUNDUP((A9-DATE(YEAR(A9),1,1)+WEEKDAY(DATE(YEAR(A9),1,1),2))/7,0) -> 2 | C9: =MONTH(A9) -> 1 | F9: =IFERROR(E9/D9,"") | I9: =IFERROR(H9/G9,"") | L9: =IFERROR(K9/J9,"") | O9: =IFERROR(N9/M9,"") | R9: =IFERROR(Q9/P9,"") | U9: =IFERROR(T9/S9,"") | X9: =IFERROR(W9/V9,"") | AA9: =IFERROR(Z9/Y9,"") | AD9: =IFERROR(AC9/AB9,"") | AG9: =IFERROR(AF9/AE9,"") | AJ9: =IFERROR(AI9/AH9,"") | AM9: =IFERROR(AL9/AK9,"") | AP9: =IFERROR(AO9/AN9,"")
A10: 46031 | B10: =ROUNDUP((A10-DATE(YEAR(A10),1,1)+WEEKDAY(DATE(YEAR(A10),1,1),2))/7,0) -> 2 | C10: =MONTH(A10) -> 1 | F10: =IFERROR(E10/D10,"") | I10: =IFERROR(H10/G10,"") | L10: =IFERROR(K10/J10,"") | O10: =IFERROR(N10/M10,"") | R10: =IFERROR(Q10/P10,"") | U10: =IFERROR(T10/S10,"") | X10: =IFERROR(W10/V10,"") | AA10: =IFERROR(Z10/Y10,"") | AD10: =IFERROR(AC10/AB10,"") | AG10: =IFERROR(AF10/AE10,"") | AJ10: =IFERROR(AI10/AH10,"") | AM10: =IFERROR(AL10/AK10,"") | AP10: =IFERROR(AO10/AN10,"")
A11: 46032 | B11: =ROUNDUP((A11-DATE(YEAR(A11),1,1)+WEEKDAY(DATE(YEAR(A11),1,1),2))/7,0) -> 2 | C11: =MONTH(A11) -> 1 | F11: =IFERROR(E11/D11,"") | I11: =IFERROR(H11/G11,"") | L11: =IFERROR(K11/J11,"") | O11: =IFERROR(N11/M11,"") | R11: =IFERROR(Q11/P11,"") | U11: =IFERROR(T11/S11,"") | X11: =IFERROR(W11/V11,"") | AA11: =IFERROR(Z11/Y11,"") | AD11: =IFERROR(AC11/AB11,"") | AG11: =IFERROR(AF11/AE11,"") | AJ11: =IFERROR(AI11/AH11,"") | AM11: =IFERROR(AL11/AK11,"") | AP11: =IFERROR(AO11/AN11,"")
A12: 46033 | B12: =ROUNDUP((A12-DATE(YEAR(A12),1,1)+WEEKDAY(DATE(YEAR(A12),1,1),2))/7,0) -> 2 | C12: =MONTH(A12) -> 1 | F12: =IFERROR(E12/D12,"") | I12: =IFERROR(H12/G12,"") | L12: =IFERROR(K12/J12,"") | O12: =IFERROR(N12/M12,"") | R12: =IFERROR(Q12/P12,"") | U12: =IFERROR(T12/S12,"") | X12: =IFERROR(W12/V12,"") | AA12: =IFERROR(Z12/Y12,"") | AD12: =IFERROR(AC12/AB12,"") | AG12: =IFERROR(AF12/AE12,"") | AJ12: =IFERROR(AI12/AH12,"") | AM12: =IFERROR(AL12/AK12,"") | AP12: =IFERROR(AO12/AN12,"")
A13: 46034 | B13: =ROUNDUP((A13-DATE(YEAR(A13),1,1)+WEEKDAY(DATE(YEAR(A13),1,1),2))/7,0) -> 3 | C13: =MONTH(A13) -> 1 | F13: =IFERROR(E13/D13,"") | I13: =IFERROR(H13/G13,"") | L13: =IFERROR(K13/J13,"") | O13: =IFERROR(N13/M13,"") | R13: =IFERROR(Q13/P13,"") | U13: =IFERROR(T13/S13,"") | X13: =IFERROR(W13/V13,"") | AA13: =IFERROR(Z13/Y13,"") | AD13: =IFERROR(AC13/AB13,"") | AG13: =IFERROR(AF13/AE13,"") | AJ13: =IFERROR(AI13/AH13,"") | AM13: =IFERROR(AL13/AK13,"") | AP13: =IFERROR(AO13/AN13,"")
A14: 46035 | B14: =ROUNDUP((A14-DATE(YEAR(A14),1,1)+WEEKDAY(DATE(YEAR(A14),1,1),2))/7,0) -> 3 | C14: =MONTH(A14) -> 1 | F14: =IFERROR(E14/D14,"") | I14: =IFERROR(H14/G14,"") | L14: =IFERROR(K14/J14,"") | O14: =IFERROR(N14/M14,"") | R14: =IFERROR(Q14/P14,"") | U14: =IFERROR(T14/S14,"") | X14: =IFERROR(W14/V14,"") | AA14: =IFERROR(Z14/Y14,"") | AD14: =IFERROR(AC14/AB14,"") | AG14: =IFERROR(AF14/AE14,"") | AJ14: =IFERROR(AI14/AH14,"") | AM14: =IFERROR(AL14/AK14,"") | AP14: =IFERROR(AO14/AN14,"")
... A61: 46082 | B61: =ROUNDUP((A61-DATE(YEAR(A61),1,1)+WEEKDAY(DATE(YEAR(A61),1,1),2))/7,0) -> 9 | C61: =MONTH(A61) -> 3 | F61: =IFERROR(E61/D61,"") | I61: =IFERROR(H61/G61,"") | L61: =IFERROR(K61/J61,"") | O61: =IFERROR(N61/M61,"") | R61: =IFERROR(Q61/P61,"") | U61: =IFERROR(T61/S61,"") | X61: =IFERROR(W61/V61,"") | AA61: =IFERROR(Z61/Y61,"") | AD61: =IFERROR(AC61/AB61,"") | AG61: =IFERROR(AF61/AE61,"") | AJ61: =IFERROR(AI61/AH61,"") | AM61: =IFERROR(AL61/AK61,"") | AP61: =IFERROR(AO61/AN61,"")
A62: 46083 | B62: =ROUNDUP((A62-DATE(YEAR(A62),1,1)+WEEKDAY(DATE(YEAR(A62),1,1),2))/7,0) -> 10 | C62: =MONTH(A62) -> 3 | D62: 10410 | E62: 12051 | F62: =IFERROR(E62/D62,"") -> 1.1576369 | G62: 0 | H62: 0 | I62: =IFERROR(H62/G62,"") | J62: 0 | K62: 0 | L62: =IFERROR(K62/J62,"") | M62: 1 | N62: 1 | O62: =IFERROR(N62/M62,"") -> 1 | P62: 3 | Q62: 3 | R62: =IFERROR(Q62/P62,"") -> 1 | S62: 10918 | T62: 5605 | U62: =IFERROR(T62/S62,"") -> 0.51337241 | V62: 400 | W62: 14 | X62: =IFERROR(W62/V62,"") -> 0.035 | Y62: 0 | Z62: 0 | AA62: =IFERROR(Z62/Y62,"") | AB62: 200000 | AC62: 210680 | AD62: =IFERROR(AC62/AB62,"") -> 1.0534 | AE62: 200000 | AF62: 210680 | AG62: =IFERROR(AF62/AE62,"") -> 1.0534 | AH62: 280 | AI62: 280.15 | AJ62: =IFERROR(AI62/AH62,"") -> 1.0005357 | AK62: 0 | AL62: 0 | AM62: =IFERROR(AL62/AK62,"") | AN62: 8 | AO62: 8 | AP62: =IFERROR(AO62/AN62,"") -> 1
A63: 46084 | B63: =ROUNDUP((A63-DATE(YEAR(A63),1,1)+WEEKDAY(DATE(YEAR(A63),1,1),2))/7,0) -> 10 | C63: =MONTH(A63) -> 3 | D63: 7860 | E63: 10653 | F63: =IFERROR(E63/D63,"") -> 1.3553435 | G63: 0 | H63: 0 | I63: =IFERROR(H63/G63,"") | J63: 0 | K63: 0 | L63: =IFERROR(K63/J63,"") | M63: 2 | N63: 1 | O63: =IFERROR(N63/M63,"") -> 0.5 | P63: 2 | Q63: 2 | R63: =IFERROR(Q63/P63,"") -> 1 | S63: 16000 | T63: 16348 | U63: =IFERROR(T63/S63,"") -> 1.02175 | V63: 0 | W63: 0 | X63: =IFERROR(W63/V63,"") | Y63: 0 | Z63: 0 | AA63: =IFERROR(Z63/Y63,"") | AB63: 0 | AC63: 0 | AD63: =IFERROR(AC63/AB63,"") | AE63: 20000 | AF63: =19900+900 -> 20800 | AG63: =IFERROR(AF63/AE63,"") -> 1.04 | AH63: 400 | AI63: 405.4 | AJ63: =IFERROR(AI63/AH63,"") -> 1.0135 | AK63: 800 | AL63: 768 | AM63: =IFERROR(AL63/AK63,"") -> 0.96 | AN63: 200 | AO63: 194 | AP63: =IFERROR(AO63/AN63,"") -> 0.97
A64: 46085 | B64: =ROUNDUP((A64-DATE(YEAR(A64),1,1)+WEEKDAY(DATE(YEAR(A64),1,1),2))/7,0) -> 10 | C64: =MONTH(A64) -> 3 | D64: 12406 | E64: 11717 | F64: =IFERROR(E64/D64,"") -> 0.94446236 | G64: 0 | H64: 0 | I64: =IFERROR(H64/G64,"") | J64: 0 | K64: 0 | L64: =IFERROR(K64/J64,"") | M64: 2 | N64: 2 | O64: =IFERROR(N64/M64,"") -> 1 | P64: 2 | Q64: 2 | R64: =IFERROR(Q64/P64,"") -> 1 | S64: 3040 | T64: 44 | U64: =IFERROR(T64/S64,"") -> 0.014473684 | V64: 1400 | W64: 1461 | X64: =IFERROR(W64/V64,"") -> 1.0435714 | Y64: 0 | Z64: 0 | AA64: =IFERROR(Z64/Y64,"") | AB64: 0 | AC64: 0 | AD64: =IFERROR(AC64/AB64,"") | AE64: 0 | AF64: 0 | AG64: =IFERROR(AF64/AE64,"") | AH64: 440 | AI64: 446.17 | AJ64: =IFERROR(AI64/AH64,"") -> 1.0140227 | AK64: 400 | AL64: 415 | AM64: =IFERROR(AL64/AK64,"") -> 1.0375 | AN64: 400 | AO64: 420 | AP64: =IFERROR(AO64/AN64,"") -> 1.05
A65: 46086 | B65: =ROUNDUP((A65-DATE(YEAR(A65),1,1)+WEEKDAY(DATE(YEAR(A65),1,1),2))/7,0) -> 10 | C65: =MONTH(A65) -> 3 | D65: 14070 | E65: 17525 | F65: =IFERROR(E65/D65,"") -> 1.2455579 | G65: 0 | H65: 0 | I65: =IFERROR(H65/G65,"") | J65: 0 | K65: 0 | L65: =IFERROR(K65/J65,"") | M65: 2 | N65: 2 | O65: =IFERROR(N65/M65,"") -> 1 | P65: 2 | Q65: 2 | R65: =IFERROR(Q65/P65,"") -> 1 | S65: 4500 | T65: 3031 | U65: =IFERROR(T65/S65,"") -> 0.67355556 | V65: 180 | W65: 0 | X65: =IFERROR(W65/V65,"") -> 0 | Y65: 0 | Z65: 0 | AA65: =IFERROR(Z65/Y65,"") | AB65: 0 | AC65: 0 | AD65: =IFERROR(AC65/AB65,"") | AE65: 0 | AF65: 0 | AG65: =IFERROR(AF65/AE65,"") | AH65: 450 | AI65: 497.25 | AJ65: =IFERROR(AI65/AH65,"") -> 1.105 | AK65: 0 | AL65: 0 | AM65: =IFERROR(AL65/AK65,"") | AN65: 180 | AO65: 217 | AP65: =IFERROR(AO65/AN65,"") -> 1.2055556 | AQ65: не было эл/энергии
A66: 46087 | B66: =ROUNDUP((A66-DATE(YEAR(A66),1,1)+WEEKDAY(DATE(YEAR(A66),1,1),2))/7,0) -> 10 | C66: =MONTH(A66) -> 3 | D66: 16167 | E66: 16044 | F66: =IFERROR(E66/D66,"") -> 0.99239191 | G66: 0 | H66: 0 | J66: 0 | K66: 0 | L66: =IFERROR(K66/J66,"") | M66: 2 | N66: 2 | O66: =IFERROR(N66/M66,"") -> 1 | P66: 1 | Q66: 1 | R66: =IFERROR(Q66/P66,"") -> 1 | S66: 7500 | T66: 7658 | U66: =IFERROR(T66/S66,"") -> 1.0210667 | V66: 220 | W66: 221 | X66: =IFERROR(W66/V66,"") -> 1.0045455 | Y66: 0 | Z66: 0 | AA66: =IFERROR(Z66/Y66,"") | AB66: 0 | AC66: 0 | AD66: =IFERROR(AC66/AB66,"") | AE66: 0 | AF66: 0 | AG66: =IFERROR(AF66/AE66,"") | AH66: 500 | AI66: 512 | AJ66: =IFERROR(AI66/AH66,"") -> 1.024 | AM66: =IFERROR(AL66/AK66,"") | AP66: =IFERROR(AO66/AN66,"")
A67: 46088 | B67: =ROUNDUP((A67-DATE(YEAR(A67),1,1)+WEEKDAY(DATE(YEAR(A67),1,1),2))/7,0) -> 10 | C67: =MONTH(A67) -> 3 | F67: =IFERROR(E67/D67,"") | I67: =IFERROR(H67/G67,"") | L67: =IFERROR(K67/J67,"") | M67: 5 | N67: 5 | O67: =IFERROR(N67/M67,"") -> 1 | R67: =IFERROR(Q67/P67,"") | U67: =IFERROR(T67/S67,"") | X67: =IFERROR(W67/V67,"") | AA67: =IFERROR(Z67/Y67,"") | AD67: =IFERROR(AC67/AB67,"") | AG67: =IFERROR(AF67/AE67,"") | AJ67: =IFERROR(AI67/AH67,"") | AM67: =IFERROR(AL67/AK67,"") | AP67: =IFERROR(AO67/AN67,"")
A68: 46089 | B68: =ROUNDUP((A68-DATE(YEAR(A68),1,1)+WEEKDAY(DATE(YEAR(A68),1,1),2))/7,0) -> 10 | C68: =MONTH(A68) -> 3 | F68: =IFERROR(E68/D68,"") | I68: =IFERROR(H68/G68,"") | L68: =IFERROR(K68/J68,"") | O68: =IFERROR(N68/M68,"") | R68: =IFERROR(Q68/P68,"") | U68: =IFERROR(T68/S68,"") | X68: =IFERROR(W68/V68,"") | AA68: =IFERROR(Z68/Y68,"") | AD68: =IFERROR(AC68/AB68,"") | AG68: =IFERROR(AF68/AE68,"") | AJ68: =IFERROR(AI68/AH68,"") | AM68: =IFERROR(AL68/AK68,"") | AP68: =IFERROR(AO68/AN68,"")
A69: 46090 | B69: =ROUNDUP((A69-DATE(YEAR(A69),1,1)+WEEKDAY(DATE(YEAR(A69),1,1),2))/7,0) -> 11 | C69: =MONTH(A69) -> 3 | F69: =IFERROR(E69/D69,"") | I69: =IFERROR(H69/G69,"") | L69: =IFERROR(K69/J69,"") | O69: =IFERROR(N69/M69,"") | R69: =IFERROR(Q69/P69,"") | U69: =IFERROR(T69/S69,"") | X69: =IFERROR(W69/V69,"") | AA69: =IFERROR(Z69/Y69,"") | AD69: =IFERROR(AC69/AB69,"") | AG69: =IFERROR(AF69/AE69,"") | AJ69: =IFERROR(AI69/AH69,"") | AM69: =IFERROR(AL69/AK69,"") | AP69: =IFERROR(AO69/AN69,"")
A70: 46091 | B70: =ROUNDUP((A70-DATE(YEAR(A70),1,1)+WEEKDAY(DATE(YEAR(A70),1,1),2))/7,0) -> 11 | C70: =MONTH(A70) -> 3 | D70: 19874 | E70: 15985 | F70: =IFERROR(E70/D70,"") -> 0.8043172 | G70: 0 | H70: 0 | I70: =IFERROR(H70/G70,"") | J70: 0 | K70: 0 | L70: =IFERROR(K70/J70,"") | M70: 1 | N70: 1 | O70: =IFERROR(N70/M70,"") -> 1 | P70: 0 | Q70: 0 | R70: =IFERROR(Q70/P70,"") | S70: 4000 | T70: 8400 | U70: =IFERROR(T70/S70,"") -> 2.1 | V70: 1260 | W70: 962.95 | X70: =IFERROR(W70/V70,"") -> 0.76424603 | Y70: 0 | Z70: 0 | AA70: =IFERROR(Z70/Y70,"") | AB70: 0 | AC70: 0 | AD70: =IFERROR(AC70/AB70,"") | AE70: 0 | AF70: 0 | AG70: =IFERROR(AF70/AE70,"") | AH70: 450 | AI70: 470.65 | AJ70: =IFERROR(AI70/AH70,"") -> 1.0458889 | AK70: 0 | AL70: 0 | AM70: =IFERROR(AL70/AK70,"") | AN70: 200 | AO70: 219 | AP70: =IFERROR(#REF!/#REF!,"")
A71: 46092 | B71: =ROUNDUP((A71-DATE(YEAR(A71),1,1)+WEEKDAY(DATE(YEAR(A71),1,1),2))/7,0) -> 11 | C71: =MONTH(A71) -> 3 | D71: 18000 | E71: 14250 | F71: =IFERROR(E71/D71,"") -> 0.79166667 | G71: 0 | H71: 0 | I71: =IFERROR(H71/G71,"") | J71: 0 | K71: 0 | L71: =IFERROR(K71/J71,"") | M71: 1 | N71: 1 | O71: =IFERROR(N71/M71,"") -> 1 | P71: 0 | Q71: 0 | R71: =IFERROR(Q71/P71,"") | S71: 4000 | T71: 5189 | U71: =IFERROR(T71/S71,"") -> 1.29725 | V71: 650 | W71: 670 | X71: =IFERROR(W71/V71,"") -> 1.0307692 | Y71: 0 | Z71: 0 | AA71: =IFERROR(Z71/Y71,"") | AB71: 0 | AC71: 0 | AD71: =IFERROR(AC71/AB71,"") | AE71: 0 | AF71: 0 | AG71: =IFERROR(AF71/AE71,"") | AH71: 200 | AI71: 184 | AJ71: =IFERROR(AI71/AH71,"") -> 0.92 | AK71: 0 | AL71: 0 | AM71: =IFERROR(AL71/AK71,"") | AN71: 0 | AO71: 0 | AP71: =IFERROR(AO71/AN71,"")
A72: 46093 | B72: =ROUNDUP((A72-DATE(YEAR(A72),1,1)+WEEKDAY(DATE(YEAR(A72),1,1),2))/7,0) -> 11 | C72: =MONTH(A72) -> 3 | D72: 15658 | E72: 13184 | F72: =IFERROR(E72/D72,"") -> 0.8419977 | G72: 0 | H72: 0 | I72: =IFERROR(H72/G72,"") | J72: 0 | K72: 0 | L72: =IFERROR(K72/J72,"") | M72: 1 | N72: 1 | O72: =IFERROR(N72/M72,"") -> 1 | P72: 3 | Q72: 3 | R72: =IFERROR(Q72/P72,"") -> 1 | S72: 10000 | T72: 10072 | U72: =IFERROR(T72/S72,"") -> 1.0072 | V72: 0 | W72: 0 | X72: =IFERROR(W72/V72,"") | Y72: 15000 | Z72: 15385 | AA72: =IFERROR(Z72/Y72,"") -> 1.0256667 | AB72: 0 | AC72: 0 | AD72: =IFERROR(AC72/AB72,"") | AE72: 0 | AF72: 0 | AG72: =IFERROR(AF72/AE72,"") | AH72: 450 | AI72: 452 | AJ72: =IFERROR(AI72/AH72,"") -> 1.0044444 | AK72: 0 | AL72: 0 | AM72: =IFERROR(AL72/AK72,"") | AN72: 0 | AO72: 0 | AP72: =IFERROR(AO72/AN72,"")
A73: 46094 | B73: =ROUNDUP((A73-DATE(YEAR(A73),1,1)+WEEKDAY(DATE(YEAR(A73),1,1),2))/7,0) -> 11 | C73: =MONTH(A73) -> 3 | D73: 10000 | E73: =1750+5100+2317+1240 -> 10407 | F73: =IFERROR(E73/D73,"") -> 1.0407 | G73: 0 | H73: 0 | I73: =IFERROR(H73/G73,"") | J73: 0 | K73: 0 | L73: =IFERROR(K73/J73,"") | M73: 4 | N73: 4 | O73: =IFERROR(N73/M73,"") -> 1 | P73: 3 | Q73: 3 | R73: =IFERROR(Q73/P73,"") -> 1 | S73: 14000 | T73: =680+698+680+670+670+680+698+680+5107+5075 -> 15638 | U73: =IFERROR(T73/S73,"") -> 1.117 | V73: 60 | W73: =60 -> 60 | X73: =IFERROR(W73/V73,"") -> 1 | Y73: 0 | Z73: 0 | AA73: =IFERROR(Z73/Y73,"") | AB73: 0 | AC73: 0 | AD73: =IFERROR(AC73/AB73,"") | AE73: 0 | AF73: 0 | AG73: =IFERROR(AF73/AE73,"") | AH73: 500 | AI73: 539 | AJ73: =IFERROR(AI73/AH73,"") -> 1.078 | AK73: 0 | AL73: 0 | AM73: =IFERROR(AL73/AK73,"") | AN73: 0 | AO73: 0 | AP73: =IFERROR(AO73/AN73,"")
A74: 46095 | B74: =ROUNDUP((A74-DATE(YEAR(A74),1,1)+WEEKDAY(DATE(YEAR(A74),1,1),2))/7,0) -> 11 | C74: =MONTH(A74) -> 3 | F74: =IFERROR(E74/D74,"") | I74: =IFERROR(H74/G74,"") | L74: =IFERROR(K74/J74,"") | O74: =IFERROR(N74/M74,"") | R74: =IFERROR(Q74/P74,"") | U74: =IFERROR(T74/S74,"") | X74: =IFERROR(W74/V74,"") | AA74: =IFERROR(Z74/Y74,"") | AD74: =IFERROR(AC74/AB74,"") | AG74: =IFERROR(AF74/AE74,"") | AJ74: =IFERROR(AI74/AH74,"") | AM74: =IFERROR(AL74/AK74,"") | AP74: =IFERROR(AO74/AN74,"")
A75: 46096 | B75: =ROUNDUP((A75-DATE(YEAR(A75),1,1)+WEEKDAY(DATE(YEAR(A75),1,1),2))/7,0) -> 11 | C75: =MONTH(A75) -> 3 | F75: =IFERROR(E75/D75,"") | I75: =IFERROR(H75/G75,"") | L75: =IFERROR(K75/J75,"") | O75: =IFERROR(N75/M75,"") | R75: =IFERROR(Q75/P75,"") | U75: =IFERROR(T75/S75,"") | X75: =IFERROR(W75/V75,"") | AA75: =IFERROR(Z75/Y75,"") | AD75: =IFERROR(AC75/AB75,"") | AG75: =IFERROR(AF75/AE75,"") | AJ75: =IFERROR(AI75/AH75,"") | AM75: =IFERROR(AL75/AK75,"") | AP75: =IFERROR(AO75/AN75,"")
A76: 46097 | B76: =ROUNDUP((A76-DATE(YEAR(A76),1,1)+WEEKDAY(DATE(YEAR(A76),1,1),2))/7,0) -> 12 | C76: =MONTH(A76) -> 3 | D76: 10000 | E76: =5787+119+4897 -> 10803 | F76: =IFERROR(E76/D76,"") -> 1.0803 | G76: 0 | H76: 0 | I76: =IFERROR(H76/G76,"") | J76: 0 | K76: 0 | L76: =IFERROR(K76/J76,"") | M76: 1 | N76: 1 | O76: =IFERROR(N76/M76,"") -> 1 | P76: 2 | Q76: 2 | R76: =IFERROR(Q76/P76,"") -> 1 | S76: 4500 | T76: =1552+1578+464 -> 3594 | U76: =IFERROR(T76/S76,"") -> 0.79866667 | V76: 800 | W76: =36.25+36.35+36.4+37.95+37.95+36.4+7.5+7.5+7.5+37.8+36.3+38+36.35+36.25+38.05+7+6+29.9+30.1+29.85+30.05+30.05+30.25+30.05+30.05+30.25+30.2+30.1+30.3+22.5+30.3+30.2+30.3+30.2+30.1+30.2+29.95+30+29.95+30.3+27.75+30.2 -> 1222.65 | X76: =IFERROR(W76/V76,"") -> 1.5283125 | Y76: 0 | Z76: 0 | AA76: =IFERROR(Z76/Y76,"") | AB76: 0 | AC76: 0 | AD76: =IFERROR(AC76/AB76,"") | AE76: 0 | AF76: 0 | AG76: =IFERROR(AF76/AE76,"") | AH76: 600 | AI76: 572 | AJ76: =IFERROR(AI76/AH76,"") -> 0.95333333 | AK76: 0 | AL76: 0 | AM76: =IFERROR(AL76/AK76,"") | AN76: 0 | AO76: 0 | AP76: =IFERROR(AO76/AN76,"")
A77: 46098 | B77: =ROUNDUP((A77-DATE(YEAR(A77),1,1)+WEEKDAY(DATE(YEAR(A77),1,1),2))/7,0) -> 12 | C77: =MONTH(A77) -> 3 | F77: =IFERROR(E77/D77,"") | I77: =IFERROR(H77/G77,"") | L77: =IFERROR(K77/J77,"") | O77: =IFERROR(N77/M77,"") | R77: =IFERROR(Q77/P77,"") | U77: =IFERROR(T77/S77,"") | X77: =IFERROR(W77/V77,"") | AA77: =IFERROR(Z77/Y77,"") | AD77: =IFERROR(AC77/AB77,"") | AG77: =IFERROR(AF77/AE77,"") | AJ77: =IFERROR(AI77/AH77,"") | AM77: =IFERROR(AL77/AK77,"") | AP77: =IFERROR(AO77/AN77,"")
A78: 46099 | B78: =ROUNDUP((A78-DATE(YEAR(A78),1,1)+WEEKDAY(DATE(YEAR(A78),1,1),2))/7,0) -> 12 | C78: =MONTH(A78) -> 3 | F78: =IFERROR(E78/D78,"") | I78: =IFERROR(H78/G78,"") | L78: =IFERROR(K78/J78,"") | O78: =IFERROR(N78/M78,"") | R78: =IFERROR(Q78/P78,"") | U78: =IFERROR(T78/S78,"") | X78: =IFERROR(W78/V78,"") | AA78: =IFERROR(Z78/Y78,"") | AD78: =IFERROR(AC78/AB78,"") | AG78: =IFERROR(AF78/AE78,"") | AJ78: =IFERROR(AI78/AH78,"") | AM78: =IFERROR(AL78/AK78,"") | AP78: =IFERROR(AO78/AN78,"")
A79: 46100 | B79: =ROUNDUP((A79-DATE(YEAR(A79),1,1)+WEEKDAY(DATE(YEAR(A79),1,1),2))/7,0) -> 12 | C79: =MONTH(A79) -> 3 | F79: =IFERROR(E79/D79,"") | I79: =IFERROR(H79/G79,"") | L79: =IFERROR(K79/J79,"") | O79: =IFERROR(N79/M79,"") | R79: =IFERROR(Q79/P79,"") | U79: =IFERROR(T79/S79,"") | X79: =IFERROR(W79/V79,"") | AA79: =IFERROR(Z79/Y79,"") | AD79: =IFERROR(AC79/AB79,"") | AG79: =IFERROR(AF79/AE79,"") | AJ79: =IFERROR(AI79/AH79,"") | AM79: =IFERROR(AL79/AK79,"") | AP79: =IFERROR(AO79/AN79,"")
A80: 46101 | B80: =ROUNDUP((A80-DATE(YEAR(A80),1,1)+WEEKDAY(DATE(YEAR(A80),1,1),2))/7,0) -> 12 | C80: =MONTH(A80) -> 3 | F80: =IFERROR(E80/D80,"") | I80: =IFERROR(H80/G80,"") | L80: =IFERROR(K80/J80,"") | O80: =IFERROR(N80/M80,"") | R80: =IFERROR(Q80/P80,"") | U80: =IFERROR(T80/S80,"") | X80: =IFERROR(W80/V80,"") | AA80: =IFERROR(Z80/Y80,"") | AD80: =IFERROR(AC80/AB80,"") | AG80: =IFERROR(AF80/AE80,"") | AJ80: =IFERROR(AI80/AH80,"") | AM80: =IFERROR(AL80/AK80,"") | AP80: =IFERROR(AO80/AN80,"")
A81: 46102 | B81: =ROUNDUP((A81-DATE(YEAR(A81),1,1)+WEEKDAY(DATE(YEAR(A81),1,1),2))/7,0) -> 12 | C81: =MONTH(A81) -> 3 | F81: =IFERROR(E81/D81,"") | I81: =IFERROR(H81/G81,"") | L81: =IFERROR(K81/J81,"") | O81: =IFERROR(N81/M81,"") | R81: =IFERROR(Q81/P81,"") | U81: =IFERROR(T81/S81,"") | X81: =IFERROR(W81/V81,"") | AA81: =IFERROR(Z81/Y81,"") | AD81: =IFERROR(AC81/AB81,"") | AG81: =IFERROR(AF81/AE81,"") | AJ81: =IFERROR(AI81/AH81,"") | AM81: =IFERROR(AL81/AK81,"") | AP81: =IFERROR(AO81/AN81,"")
A82: 46103 | B82: =ROUNDUP((A82-DATE(YEAR(A82),1,1)+WEEKDAY(DATE(YEAR(A82),1,1),2))/7,0) -> 12 | C82: =MONTH(A82) -> 3 | F82: =IFERROR(E82/D82,"") | I82: =IFERROR(H82/G82,"") | L82: =IFERROR(K82/J82,"") | O82: =IFERROR(N82/M82,"") | R82: =IFERROR(Q82/P82,"") | U82: =IFERROR(T82/S82,"") | X82: =IFERROR(W82/V82,"") | AA82: =IFERROR(Z82/Y82,"") | AD82: =IFERROR(AC82/AB82,"") | AG82: =IFERROR(AF82/AE82,"") | AJ82: =IFERROR(AI82/AH82,"") | AM82: =IFERROR(AL82/AK82,"") | AP82: =IFERROR(AO82/AN82,"")
A83: 46104 | B83: =ROUNDUP((A83-DATE(YEAR(A83),1,1)+WEEKDAY(DATE(YEAR(A83),1,1),2))/7,0) -> 13 | C83: =MONTH(A83) -> 3 | F83: =IFERROR(E83/D83,"") | I83: =IFERROR(H83/G83,"") | L83: =IFERROR(K83/J83,"") | O83: =IFERROR(N83/M83,"") | R83: =IFERROR(Q83/P83,"") | U83: =IFERROR(T83/S83,"") | X83: =IFERROR(W83/V83,"") | AA83: =IFERROR(Z83/Y83,"") | AD83: =IFERROR(AC83/AB83,"") | AG83: =IFERROR(AF83/AE83,"") | AJ83: =IFERROR(AI83/AH83,"") | AM83: =IFERROR(AL83/AK83,"") | AP83: =IFERROR(AO83/AN83,"")
A84: 46105 | B84: =ROUNDUP((A84-DATE(YEAR(A84),1,1)+WEEKDAY(DATE(YEAR(A84),1,1),2))/7,0) -> 13 | C84: =MONTH(A84) -> 3 | F84: =IFERROR(E84/D84,"") | I84: =IFERROR(H84/G84,"") | L84: =IFERROR(K84/J84,"") | O84: =IFERROR(N84/M84,"") | R84: =IFERROR(Q84/P84,"") | U84: =IFERROR(T84/S84,"") | X84: =IFERROR(W84/V84,"") | AA84: =IFERROR(Z84/Y84,"") | AD84: =IFERROR(AC84/AB84,"") | AG84: =IFERROR(AF84/AE84,"") | AJ84: =IFERROR(AI84/AH84,"") | AM84: =IFERROR(AL84/AK84,"") | AP84: =IFERROR(AO84/AN84,"")
A85: 46106 | B85: =ROUNDUP((A85-DATE(YEAR(A85),1,1)+WEEKDAY(DATE(YEAR(A85),1,1),2))/7,0) -> 13 | C85: =MONTH(A85) -> 3 | F85: =IFERROR(E85/D85,"") | I85: =IFERROR(H85/G85,"") | L85: =IFERROR(K85/J85,"") | O85: =IFERROR(N85/M85,"") | R85: =IFERROR(Q85/P85,"") | U85: =IFERROR(T85/S85,"") | X85: =IFERROR(W85/V85,"") | AA85: =IFERROR(Z85/Y85,"") | AD85: =IFERROR(AC85/AB85,"") | AG85: =IFERROR(AF85/AE85,"") | AJ85: =IFERROR(AI85/AH85,"") | AM85: =IFERROR(AL85/AK85,"") | AP85: =IFERROR(AO85/AN85,"")
A86: 46107 | B86: =ROUNDUP((A86-DATE(YEAR(A86),1,1)+WEEKDAY(DATE(YEAR(A86),1,1),2))/7,0) -> 13 | C86: =MONTH(A86) -> 3 | F86: =IFERROR(E86/D86,"") | I86: =IFERROR(H86/G86,"") | L86: =IFERROR(K86/J86,"") | O86: =IFERROR(N86/M86,"") | R86: =IFERROR(Q86/P86,"") | U86: =IFERROR(T86/S86,"") | X86: =IFERROR(W86/V86,"") | AA86: =IFERROR(Z86/Y86,"") | AD86: =IFERROR(AC86/AB86,"") | AG86: =IFERROR(AF86/AE86,"") | AJ86: =IFERROR(AI86/AH86,"") | AM86: =IFERROR(AL86/AK86,"") | AP86: =IFERROR(AO86/AN86,"")
...

Sheet Реестр_План_Тех
A1: =Реестр_План_Факт!A1 -> Дата | B1: =Реестр_План_Факт!B1 -> Неделя | C1: =Реестр_План_Факт!C1 -> Месяц | D1: =Реестр_План_Факт!D1 -> План Б2.Б3,Б4, м.пог. | E1: =Реестр_План_Факт!E1 -> Факт Б2.Б3,Б4, м.пог. | F1: =Реестр_План_Факт!F1 -> % выполнения Б2.Б3,Б4 | G1: =Реестр_План_Факт!G1 -> План цветная печать, м.пог. | H1: =Реестр_План_Факт!H1 -> Факт цветная печать, м.пог. | ... AP1: =Реестр_План_Факт!AP1 -> % выполнения флис(тумблировние),кг
A2: =Реестр_План_Факт!A2 -> 46023 | B2: =Реестр_План_Факт!B2 -> 1 | C2: =Реестр_План_Факт!C2 -> 1 | D2: =Реестр_План_Факт!D2 -> 0 | E2: =Реестр_План_Факт!E2 -> 0 | F2: =Реестр_План_Факт!F2 | G2: =Реестр_План_Факт!G2 -> 0 | H2: =Реестр_План_Факт!H2 -> 0 | ... AQ2: =Реестр_План_Факт!AQ2 -> 0
A3: =Реестр_План_Факт!A3 -> 46024 | B3: =Реестр_План_Факт!B3 -> 1 | C3: =Реестр_План_Факт!C3 -> 1 | D3: =Реестр_План_Факт!D3 -> 0 | E3: =Реестр_План_Факт!E3 -> 0 | F3: =Реестр_План_Факт!F3 | G3: =Реестр_План_Факт!G3 -> 0 | H3: =Реестр_План_Факт!H3 -> 0 | ... AQ3: =Реестр_План_Факт!AQ3 -> 0
A4: =Реестр_План_Факт!A4 -> 46025 | B4: =Реестр_План_Факт!B4 -> 1 | C4: =Реестр_План_Факт!C4 -> 1 | D4: =Реестр_План_Факт!D4 -> 0 | E4: =Реестр_План_Факт!E4 -> 0 | F4: =Реестр_План_Факт!F4 | G4: =Реестр_План_Факт!G4 -> 0 | H4: =Реестр_План_Факт!H4 -> 0 | ... AQ4: =Реестр_План_Факт!AQ4 -> 0
A5: =Реестр_План_Факт!A5 -> 46026 | B5: =Реестр_План_Факт!B5 -> 1 | C5: =Реестр_План_Факт!C5 -> 1 | D5: =Реестр_План_Факт!D5 -> 0 | E5: =Реестр_План_Факт!E5 -> 0 | F5: =Реестр_План_Факт!F5 | G5: =Реестр_План_Факт!G5 -> 0 | H5: =Реестр_План_Факт!H5 -> 0 | ... AQ5: =Реестр_План_Факт!AQ5 -> 0
A6: =Реестр_План_Факт!A6 -> 46027 | B6: =Реестр_План_Факт!B6 -> 2 | C6: =Реестр_План_Факт!C6 -> 1 | D6: =Реестр_План_Факт!D6 -> 0 | E6: =Реестр_План_Факт!E6 -> 0 | F6: =Реестр_План_Факт!F6 | G6: =Реестр_План_Факт!G6 -> 0 | H6: =Реестр_План_Факт!H6 -> 0 | ... AQ6: =Реестр_План_Факт!AQ6 -> 0
A7: =Реестр_План_Факт!A7 -> 46028 | B7: =Реестр_План_Факт!B7 -> 2 | C7: =Реестр_План_Факт!C7 -> 1 | D7: =Реестр_План_Факт!D7 -> 0 | E7: =Реестр_План_Факт!E7 -> 0 | F7: =Реестр_План_Факт!F7 | G7: =Реестр_План_Факт!G7 -> 0 | H7: =Реестр_План_Факт!H7 -> 0 | ... AQ7: =Реестр_План_Факт!AQ7 -> 0
A8: =Реестр_План_Факт!A8 -> 46029 | B8: =Реестр_План_Факт!B8 -> 2 | C8: =Реестр_План_Факт!C8 -> 1 | D8: =Реестр_План_Факт!D8 -> 0 | E8: =Реестр_План_Факт!E8 -> 0 | F8: =Реестр_План_Факт!F8 | G8: =Реестр_План_Факт!G8 -> 0 | H8: =Реестр_План_Факт!H8 -> 0 | ... AQ8: =Реестр_План_Факт!AQ8 -> 0
A9: =Реестр_План_Факт!A9 -> 46030 | B9: =Реестр_План_Факт!B9 -> 2 | C9: =Реестр_План_Факт!C9 -> 1 | D9: =Реестр_План_Факт!D9 -> 0 | E9: =Реестр_План_Факт!E9 -> 0 | F9: =Реестр_План_Факт!F9 | G9: =Реестр_План_Факт!G9 -> 0 | H9: =Реестр_План_Факт!H9 -> 0 | ... AQ9: =Реестр_План_Факт!AQ9 -> 0
A10: =Реестр_План_Факт!A10 -> 46031 | B10: =Реестр_План_Факт!B10 -> 2 | C10: =Реестр_План_Факт!C10 -> 1 | D10: =Реестр_План_Факт!D10 -> 0 | E10: =Реестр_План_Факт!E10 -> 0 | F10: =Реестр_План_Факт!F10 | G10: =Реестр_План_Факт!G10 -> 0 | H10: =Реестр_План_Факт!H10 -> 0 | ... AQ10: =Реестр_План_Факт!AQ10 -> 0
A11: =Реестр_План_Факт!A11 -> 46032 | B11: =Реестр_План_Факт!B11 -> 2 | C11: =Реестр_План_Факт!C11 -> 1 | D11: =Реестр_План_Факт!D11 -> 0 | E11: =Реестр_План_Факт!E11 -> 0 | F11: =Реестр_План_Факт!F11 | G11: =Реестр_План_Факт!G11 -> 0 | H11: =Реестр_План_Факт!H11 -> 0 | ... AQ11: =Реестр_План_Факт!AQ11 -> 0
A12: =Реестр_План_Факт!A12 -> 46033 | B12: =Реестр_План_Факт!B12 -> 2 | C12: =Реестр_План_Факт!C12 -> 1 | D12: =Реестр_План_Факт!D12 -> 0 | E12: =Реестр_План_Факт!E12 -> 0 | F12: =Реестр_План_Факт!F12 | G12: =Реестр_План_Факт!G12 -> 0 | H12: =Реестр_План_Факт!H12 -> 0 | ... AQ12: =Реестр_План_Факт!AQ12 -> 0
A13: =Реестр_План_Факт!A13 -> 46034 | B13: =Реестр_План_Факт!B13 -> 3 | C13: =Реестр_План_Факт!C13 -> 1 | D13: =Реестр_План_Факт!D13 -> 0 | E13: =Реестр_План_Факт!E13 -> 0 | F13: =Реестр_План_Факт!F13 | G13: =Реестр_План_Факт!G13 -> 0 | H13: =Реестр_План_Факт!H13 -> 0 | ... AQ13: =Реестр_План_Факт!AQ13 -> 0
... A366: =Реестр_План_Факт!A366 -> 46387 | B366: =Реестр_План_Факт!B366 -> 53 | C366: =Реестр_План_Факт!C366 -> 12 | D366: =Реестр_План_Факт!D366 -> 0 | E366: =Реестр_План_Факт!E366 -> 0 | F366: =Реестр_План_Факт!F366 | G366: =Реестр_План_Факт!G366 -> 0 | H366: =Реестр_План_Факт!H366 -> 0 | ... AQ366: =Реестр_План_Факт!AQ366 -> 0

Sheet Карантин
A1: Дата и время создания | B1: № задачи Bitrix24 | C1: Причина(кратко) | D1: Дата и время решения | E1: Часы до решения Число | F1: Часы до Решения | G1: МесяцГод | H1: Горячие клавиши
A2: 46080.501 | B2: 35859 | C2: расслаивается | D2: 46080.506 | E2: =IF(OR(A2="",D2=""),"",(D2-A2)*24) -> 0.11666667 | F2: =IF(OR(A2="",D2=""),"",INT((D2-A2)*24)&" час "&ROUND(((D2-A2)*24-INT((D2-A2)*24))*60,0)&" минут") -> 0 час 7 минут | G2: =IF(D2="","",TEXT(D2,"[$-419]mmmm yyyy")) -> февраль 2026 | H2: Дата | I2: Ctrl + ;
A3: 46083.541 | B3: 35715 | C3: помарки, синие подтёки | D3: 46083.628 | E3: =IF(OR(A3="",D3=""),"",(D3-A3)*24) -> 2.1 | F3: =IF(OR(A3="",D3=""),"",INT((D3-A3)*24)&" час "&ROUND(((D3-A3)*24-INT((D3-A3)*24))*60,0)&" минут") -> 2 час 6 минут | G3: =IF(D3="","",TEXT(D3,"[$-419]mmmm yyyy")) -> март 2026 | H3: Время | I3: Ctrl + Shift + ;
A4: 46083.626 | B4: 36059 | C4: неравномерная отделка | D4: 46083.698 | E4: =IF(OR(A4="",D4=""),"",(D4-A4)*24) -> 1.7333333 | F4: =IF(OR(A4="",D4=""),"",INT((D4-A4)*24)&" час "&ROUND(((D4-A4)*24-INT((D4-A4)*24))*60,0)&" минут") -> 1 час 44 минут | G4: =IF(D4="","",TEXT(D4,"[$-419]mmmm yyyy")) -> март 2026 | H4: Обязательно для заполнения
A5: 46083.677 | B5: 36001 | C5: расслаивается | D5: 46083.683 | E5: =IF(OR(A5="",D5=""),"",(D5-A5)*24) -> 0.13333333 | F5: =IF(OR(A5="",D5=""),"",INT((D5-A5)*24)&" час "&ROUND(((D5-A5)*24-INT((D5-A5)*24))*60,0)&" минут") -> 0 час 8 минут | G5: =IF(D5="","",TEXT(D5,"[$-419]mmmm yyyy")) -> март 2026
A6: 46083.678 | B6: 36001 | C6: расслаивается | D6: 46083.684 | E6: =IF(OR(A6="",D6=""),"",(D6-A6)*24) -> 0.13333333 | F6: =IF(OR(A6="",D6=""),"",INT((D6-A6)*24)&" час "&ROUND(((D6-A6)*24-INT((D6-A6)*24))*60,0)&" минут") -> 0 час 8 минут | G6: =IF(D6="","",TEXT(D6,"[$-419]mmmm yyyy")) -> март 2026
A7: 46084.546 | B7: 36085 | C7: расслаивается | D7: 46084.562 | E7: =IF(OR(A7="",D7=""),"",(D7-A7)*24) -> 0.4 | F7: =IF(OR(A7="",D7=""),"",INT((D7-A7)*24)&" час "&ROUND(((D7-A7)*24-INT((D7-A7)*24))*60,0)&" минут") -> 0 час 24 минут | G7: =IF(D7="","",TEXT(D7,"[$-419]mmmm yyyy")) -> март 2026
A8: 46085.374 | B8: 35715 | C8: помарки, синие подтёки | D8: 46085.496 | E8: =IF(OR(A8="",D8=""),"",(D8-A8)*24) -> 2.9166667 | F8: =IF(OR(A8="",D8=""),"",INT((D8-A8)*24)&" час "&ROUND(((D8-A8)*24-INT((D8-A8)*24))*60,0)&" минут") -> 2 час 55 минут | G8: =IF(D8="","",TEXT(D8,"[$-419]mmmm yyyy")) -> март 2026
A9: 46087.408 | B9: 36089 | C9: Адгезия | D9: 46087.671 | E9: =IF(OR(A9="",D9=""),"",(D9-A9)*24) -> 6.3166667 | F9: =IF(OR(A9="",D9=""),"",INT((D9-A9)*24)&" час "&ROUND(((D9-A9)*24-INT((D9-A9)*24))*60,0)&" минут") -> 6 час 19 минут | G9: =IF(D9="","",TEXT(D9,"[$-419]mmmm yyyy")) -> март 2026
A10: 46092.333 | B10: 35953 | C10: Не соот НД( разр нагр о) | D10: 46092.462 | E10: =IF(OR(A10="",D10=""),"",(D10-A10)*24) -> 3.0833333 | F10: =IF(OR(A10="",D10=""),"",INT((D10-A10)*24)&" час "&ROUND(((D10-A10)*24-INT((D10-A10)*24))*60,0)&" минут") -> 3 час 5 минут | G10: =IF(D10="","",TEXT(D10,"[$-419]mmmm yyyy")) -> март 2026
A11: 46093.649 | B11: 35859 | C11: не соотв НД | D11: 46093.662 | E11: =IF(OR(A11="",D11=""),"",(D11-A11)*24) -> 0.31666667 | F11: =IF(OR(A11="",D11=""),"",INT((D11-A11)*24)&" час "&ROUND(((D11-A11)*24-INT((D11-A11)*24))*60,0)&" минут") -> 0 час 19 минут | G11: =IF(D11="","",TEXT(D11,"[$-419]mmmm yyyy")) -> март 2026
A12: 46094.383 | B12: 35859 | C12: расслаивается, скрутка тип С | D12: 46094.463 | E12: =IF(OR(A12="",D12=""),"",(D12-A12)*24) -> 1.9 | F12: =IF(OR(A12="",D12=""),"",INT((D12-A12)*24)&" час "&ROUND(((D12-A12)*24-INT((D12-A12)*24))*60,0)&" минут") -> 1 час 54 минут | G12: =IF(D12="","",TEXT(D12,"[$-419]mmmm yyyy")) -> март 2026
A13: 46098.392 | B13: 36217 | C13: Не соот НД( м/о) | D13: 46098.422 | E13: =IF(OR(A13="",D13=""),"",(D13-A13)*24) -> 0.7 | F13: =IF(OR(A13="",D13=""),"",INT((D13-A13)*24)&" час "&ROUND(((D13-A13)*24-INT((D13-A13)*24))*60,0)&" минут") -> 0 час 42 минут | G13: =IF(D13="","",TEXT(D13,"[$-419]mmmm yyyy")) -> март 2026
A14: 46099 | B14: 35631 | C14: не соот НД ( В/О) | D14: 46099 | E14: =IF(OR(A14="",D14=""),"",(D14-A14)*24) -> 0 | F14: =IF(OR(A14="",D14=""),"",INT((D14-A14)*24)&" час "&ROUND(((D14-A14)*24-INT((D14-A14)*24))*60,0)&" минут") -> 0 час 0 минут | G14: =IF(D14="","",TEXT(D14,"[$-419]mmmm yyyy")) -> март 2026
A15: 46100.548 | B15: 35631 | C15: не соот НД( В/О после стирок) | D15: 46100.548 | E15: =IF(OR(A15="",D15=""),"",(D15-A15)*24) -> 0 | F15: =IF(OR(A15="",D15=""),"",INT((D15-A15)*24)&" час "&ROUND(((D15-A15)*24-INT((D15-A15)*24))*60,0)&" минут") -> 0 час 0 минут | G15: =IF(D15="","",TEXT(D15,"[$-419]mmmm yyyy")) -> март 2026
E16: =IF(OR(A16="",D16=""),"",(D16-A16)*24) | F16: =IF(OR(A16="",D16=""),"",INT((D16-A16)*24)&" час "&ROUND(((D16-A16)*24-INT((D16-A16)*24))*60,0)&" минут") | G16: =IF(D16="","",TEXT(D16,"ММММ ГГГГ"))
E17: =IF(OR(A17="",D17=""),"",(D17-A17)*24) | F17: =IF(OR(A17="",D17=""),"",INT((D17-A17)*24)&" час "&ROUND(((D17-A17)*24-INT((D17-A17)*24))*60,0)&" минут") | G17: =IF(D17="","",TEXT(D17,"ММММ ГГГГ"))
E18: =IF(OR(A18="",D18=""),"",(D18-A18)*24) | F18: =IF(OR(A18="",D18=""),"",INT((D18-A18)*24)&" час "&ROUND(((D18-A18)*24-INT((D18-A18)*24))*60,0)&" минут") | G18: =IF(D18="","",TEXT(D18,"ММММ ГГГГ"))
E19: =IF(OR(A19="",D19=""),"",(D19-A19)*24) | F19: =IF(OR(A19="",D19=""),"",INT((D19-A19)*24)&" час "&ROUND(((D19-A19)*24-INT((D19-A19)*24))*60,0)&" минут") | G19: =IF(D19="","",TEXT(D19,"ММММ ГГГГ"))
E20: =IF(OR(A20="",D20=""),"",(D20-A20)*24) | F20: =IF(OR(A20="",D20=""),"",INT((D20-A20)*24)&" час "&ROUND(((D20-A20)*24-INT((D20-A20)*24))*60,0)&" минут") | G20: =IF(D20="","",TEXT(D20,"ММММ ГГГГ"))
E21: =IF(OR(A21="",D21=""),"",(D21-A21)*24) | F21: =IF(OR(A21="",D21=""),"",INT((D21-A21)*24)&" час "&ROUND(((D21-A21)*24-INT((D21-A21)*24))*60,0)&" минут") | G21: =IF(D21="","",TEXT(D21,"ММММ ГГГГ"))
E22: =IF(OR(A22="",D22=""),"",(D22-A22)*24) | F22: =IF(OR(A22="",D22=""),"",INT((D22-A22)*24)&" час "&ROUND(((D22-A22)*24-INT((D22-A22)*24))*60,0)&" минут") | G22: =IF(D22="","",TEXT(D22,"ММММ ГГГГ"))
E23: =IF(OR(A23="",D23=""),"",(D23-A23)*24) | F23: =IF(OR(A23="",D23=""),"",INT((D23-A23)*24)&" час "&ROUND(((D23-A23)*24-INT((D23-A23)*24))*60,0)&" минут") | G23: =IF(D23="","",TEXT(D23,"ММММ ГГГГ"))
E24: =IF(OR(A24="",D24=""),"",(D24-A24)*24) | F24: =IF(OR(A24="",D24=""),"",INT((D24-A24)*24)&" час "&ROUND(((D24-A24)*24-INT((D24-A24)*24))*60,0)&" минут") | G24: =IF(D24="","",TEXT(D24,"ММММ ГГГГ"))
E25: =IF(OR(A25="",D25=""),"",(D25-A25)*24) | F25: =IF(OR(A25="",D25=""),"",INT((D25-A25)*24)&" час "&ROUND(((D25-A25)*24-INT((D25-A25)*24))*60,0)&" минут") | G25: =IF(D25="","",TEXT(D25,"ММММ ГГГГ"))
E26: =IF(OR(A26="",D26=""),"",(D26-A26)*24) | F26: =IF(OR(A26="",D26=""),"",INT((D26-A26)*24)&" час "&ROUND(((D26-A26)*24-INT((D26-A26)*24))*60,0)&" минут") | G26: =IF(D26="","",TEXT(D26,"ММММ ГГГГ"))
E27: =IF(OR(A27="",D27=""),"",(D27-A27)*24) | F27: =IF(OR(A27="",D27=""),"",INT((D27-A27)*24)&" час "&ROUND(((D27-A27)*24-INT((D27-A27)*24))*60,0)&" минут") | G27: =IF(D27="","",TEXT(D27,"ММММ ГГГГ"))
... E1000: =IF(OR(A1000="",D1000=""),"",(D1000-A1000)*24) | F1000: =IF(OR(A1000="",D1000=""),"",INT((D1000-A1000)*24)&" час "&ROUND(((D1000-A1000)*24-INT((D1000-A1000)*24))*60,0)&" минут") | G1000: =IF(D1000="","",TEXT(D1000,"ММММ ГГГГ"))
F1001: =IF(OR(A1001="",D1001=""),"",INT((D1001-A1001)*24)&" час "&ROUND(((D1001-A1001)*24-INT((D1001-A1001)*24))*60,0)&" минут")
F1002: =IF(OR(A1002="",D1002=""),"",INT((D1002-A1002)*24)&" час "&ROUND(((D1002-A1002)*24-INT((D1002-A1002)*24))*60,0)&" минут")
F1003: =IF(OR(A1003="",D1003=""),"",INT((D1003-A1003)*24)&" час "&ROUND(((D1003-A1003)*24-INT((D1003-A1003)*24))*60,0)&" минут")
F1004: =IF(OR(A1004="",D1004=""),"",INT((D1004-A1004)*24)&" час "&ROUND(((D1004-A1004)*24-INT((D1004-A1004)*24))*60,0)&" минут")
F1005: =IF(OR(A1005="",D1005=""),"",INT((D1005-A1005)*24)&" час "&ROUND(((D1005-A1005)*24-INT((D1005-A1005)*24))*60,0)&" минут")
F1006: =IF(OR(A1006="",D1006=""),"",INT((D1006-A1006)*24)&" час "&ROUND(((D1006-A1006)*24-INT((D1006-A1006)*24))*60,0)&" минут")
F1007: =IF(OR(A1007="",D1007=""),"",INT((D1007-A1007)*24)&" час "&ROUND(((D1007-A1007)*24-INT((D1007-A1007)*24))*60,0)&" минут")
F1008: =IF(OR(A1008="",D1008=""),"",INT((D1008-A1008)*24)&" час "&ROUND(((D1008-A1008)*24-INT((D1008-A1008)*24))*60,0)&" минут")
F1009: =IF(OR(A1009="",D1009=""),"",INT((D1009-A1009)*24)&" час "&ROUND(((D1009-A1009)*24-INT((D1009-A1009)*24))*60,0)&" минут")
F1010: =IF(OR(A1010="",D1010=""),"",INT((D1010-A1010)*24)&" час "&ROUND(((D1010-A1010)*24-INT((D1010-A1010)*24))*60,0)&" минут")
F1011: =IF(OR(A1011="",D1011=""),"",INT((D1011-A1011)*24)&" час "&ROUND(((D1011-A1011)*24-INT((D1011-A1011)*24))*60,0)&" минут")
F1012: =IF(OR(A1012="",D1012=""),"",INT((D1012-A1012)*24)&" час "&ROUND(((D1012-A1012)*24-INT((D1012-A1012)*24))*60,0)&" минут")
...

Sheet Сортность
A1: Дата | B1: Неделя Дата | C1: Месяц Дата | D1: Сырье,% | E1: Промежуточный контроль,% | F1: Готовая ткань,% | G1: Недели | H1: Сырье Неделя,% | I1: Промежуточный контроль Неделя,% | J1: Готовая ткань Неделя,% | K1: Месяц | L1: Сырье Месяц,% | M1: Промежуточный контроль Месяц,% | N1: Готовая ткань Месяц,%
A2: 46023 | B2: =WEEKNUM(A2,2) -> 1 | C2: =MONTH(A2) -> 1 | G2: 1 | H2: =IFERROR(AVERAGE(D2:D5),"") | I2: =IFERROR(AVERAGE(E2:E5),"") | J2: =IFERROR(AVERAGE(F2:F5),"") | K2: Январь | L2: =IFERROR(AVERAGEIF($C:$C,1,D:D),"") | M2: =IFERROR(AVERAGEIF($C:$C,1,E:E),"") | N2: =IFERROR(AVERAGEIF($C:$C,1,F:F),"")
A3: 46024 | B3: =WEEKNUM(A3,2) -> 1 | C3: =MONTH(A3) -> 1 | G3: 2 | H3: =IFERROR(AVERAGE(INDEX(D:D,6+(ROW(A1)-1)*7):INDEX(D:D,12+(ROW(A1)-1)*7)),"") | I3: =IFERROR(AVERAGE(INDEX(E:E,6+(ROW(B1)-1)*7):INDEX(E:E,12+(ROW(B1)-1)*7)),"") | J3: =IFERROR(AVERAGE(INDEX(F:F,6+(ROW(C1)-1)*7):INDEX(F:F,12+(ROW(C1)-1)*7)),"") | K3: Февраль | L3: =IFERROR(AVERAGEIF($C:$C,2,D:D),"") | M3: =IFERROR(AVERAGEIF($C:$C,2,E:E),"") | N3: =IFERROR(AVERAGEIF($C:$C,2,F:F),"") -> 99.06
A4: 46025 | B4: =WEEKNUM(A4,2) -> 1 | C4: =MONTH(A4) -> 1 | G4: 3 | H4: =IFERROR(AVERAGE(INDEX(D:D,6+(ROW(A2)-1)*7):INDEX(D:D,12+(ROW(A2)-1)*7)),"") | I4: =IFERROR(AVERAGE(INDEX(E:E,6+(ROW(B2)-1)*7):INDEX(E:E,12+(ROW(B2)-1)*7)),"") | J4: =IFERROR(AVERAGE(INDEX(F:F,6+(ROW(C2)-1)*7):INDEX(F:F,12+(ROW(C2)-1)*7)),"") | K4: Март | L4: =IFERROR(AVERAGEIF($C:$C,3,D:D),"") -> 98.679286 | M4: =IFERROR(AVERAGEIF($C:$C,3,E:E),"") -> 93.616429 | N4: =IFERROR(AVERAGEIF($C:$C,3,F:F),"") -> 98.235
A5: 46026 | B5: =WEEKNUM(A5,2) -> 1 | C5: =MONTH(A5) -> 1 | G5: 4 | H5: =IFERROR(AVERAGE(INDEX(D:D,6+(ROW(A3)-1)*7):INDEX(D:D,12+(ROW(A3)-1)*7)),"") | I5: =IFERROR(AVERAGE(INDEX(E:E,6+(ROW(B3)-1)*7):INDEX(E:E,12+(ROW(B3)-1)*7)),"") | J5: =IFERROR(AVERAGE(INDEX(F:F,6+(ROW(C3)-1)*7):INDEX(F:F,12+(ROW(C3)-1)*7)),"") | K5: Апрель | L5: =IFERROR(AVERAGEIF($C:$C,4,D:D),"") | M5: =IFERROR(AVERAGEIF($C:$C,4,E:E),"") | N5: =IFERROR(AVERAGEIF($C:$C,4,F:F),"")
A6: 46027 | B6: =WEEKNUM(A6,2) -> 2 | C6: =MONTH(A6) -> 1 | G6: 5 | H6: =IFERROR(AVERAGE(INDEX(D:D,6+(ROW(A4)-1)*7):INDEX(D:D,12+(ROW(A4)-1)*7)),"") | I6: =IFERROR(AVERAGE(INDEX(E:E,6+(ROW(B4)-1)*7):INDEX(E:E,12+(ROW(B4)-1)*7)),"") | J6: =IFERROR(AVERAGE(INDEX(F:F,6+(ROW(C4)-1)*7):INDEX(F:F,12+(ROW(C4)-1)*7)),"") | K6: Май | L6: =IFERROR(AVERAGEIF($C:$C,5,D:D),"") | M6: =IFERROR(AVERAGEIF($C:$C,5,E:E),"") | N6: =IFERROR(AVERAGEIF($C:$C,5,F:F),"")
A7: 46028 | B7: =WEEKNUM(A7,2) -> 2 | C7: =MONTH(A7) -> 1 | G7: 6 | H7: =IFERROR(AVERAGE(INDEX(D:D,6+(ROW(A5)-1)*7):INDEX(D:D,12+(ROW(A5)-1)*7)),"") | I7: =IFERROR(AVERAGE(INDEX(E:E,6+(ROW(B5)-1)*7):INDEX(E:E,12+(ROW(B5)-1)*7)),"") | J7: =IFERROR(AVERAGE(INDEX(F:F,6+(ROW(C5)-1)*7):INDEX(F:F,12+(ROW(C5)-1)*7)),"") | K7: Июнь | L7: =IFERROR(AVERAGEIF($C:$C,6,D:D),"") | M7: =IFERROR(AVERAGEIF($C:$C,6,E:E),"") | N7: =IFERROR(AVERAGEIF($C:$C,6,F:F),"")
A8: 46029 | B8: =WEEKNUM(A8,2) -> 2 | C8: =MONTH(A8) -> 1 | G8: 7 | H8: =IFERROR(AVERAGE(INDEX(D:D,6+(ROW(A6)-1)*7):INDEX(D:D,12+(ROW(A6)-1)*7)),"") | I8: =IFERROR(AVERAGE(INDEX(E:E,6+(ROW(B6)-1)*7):INDEX(E:E,12+(ROW(B6)-1)*7)),"") | J8: =IFERROR(AVERAGE(INDEX(F:F,6+(ROW(C6)-1)*7):INDEX(F:F,12+(ROW(C6)-1)*7)),"") | K8: Июль | L8: =IFERROR(AVERAGEIF($C:$C,7,D:D),"") | M8: =IFERROR(AVERAGEIF($C:$C,7,E:E),"") | N8: =IFERROR(AVERAGEIF($C:$C,7,F:F),"")
A9: 46030 | B9: =WEEKNUM(A9,2) -> 2 | C9: =MONTH(A9) -> 1 | G9: 8 | H9: =IFERROR(AVERAGE(INDEX(D:D,6+(ROW(A7)-1)*7):INDEX(D:D,12+(ROW(A7)-1)*7)),"") | I9: =IFERROR(AVERAGE(INDEX(E:E,6+(ROW(B7)-1)*7):INDEX(E:E,12+(ROW(B7)-1)*7)),"") | J9: =IFERROR(AVERAGE(INDEX(F:F,6+(ROW(C7)-1)*7):INDEX(F:F,12+(ROW(C7)-1)*7)),"") | K9: Август | L9: =IFERROR(AVERAGEIF($C:$C,8,D:D),"") | M9: =IFERROR(AVERAGEIF($C:$C,8,E:E),"") | N9: =IFERROR(AVERAGEIF($C:$C,8,F:F),"")
A10: 46031 | B10: =WEEKNUM(A10,2) -> 2 | C10: =MONTH(A10) -> 1 | G10: 9 | H10: =IFERROR(AVERAGE(INDEX(D:D,6+(ROW(A8)-1)*7):INDEX(D:D,12+(ROW(A8)-1)*7)),"") | I10: =IFERROR(AVERAGE(INDEX(E:E,6+(ROW(B8)-1)*7):INDEX(E:E,12+(ROW(B8)-1)*7)),"") | J10: =IFERROR(AVERAGE(INDEX(F:F,6+(ROW(C8)-1)*7):INDEX(F:F,12+(ROW(C8)-1)*7)),"") -> 99.06 | K10: Сентябрь | L10: =IFERROR(AVERAGEIF($C:$C,9,D:D),"") | M10: =IFERROR(AVERAGEIF($C:$C,9,E:E),"") | N10: =IFERROR(AVERAGEIF($C:$C,9,F:F),"")
A11: 46032 | B11: =WEEKNUM(A11,2) -> 2 | C11: =MONTH(A11) -> 1 | G11: 10 | H11: =IFERROR(AVERAGE(INDEX(D:D,6+(ROW(A9)-1)*7):INDEX(D:D,12+(ROW(A9)-1)*7)),"") -> 99.432 | I11: =IFERROR(AVERAGE(INDEX(E:E,6+(ROW(B9)-1)*7):INDEX(E:E,12+(ROW(B9)-1)*7)),"") -> 89.736 | J11: =IFERROR(AVERAGE(INDEX(F:F,6+(ROW(C9)-1)*7):INDEX(F:F,12+(ROW(C9)-1)*7)),"") -> 97.766 | K11: Октябрь | L11: =IFERROR(AVERAGEIF($C:$C,10,D:D),"") | M11: =IFERROR(AVERAGEIF($C:$C,10,E:E),"") | N11: =IFERROR(AVERAGEIF($C:$C,10,F:F),"")
A12: 46033 | B12: =WEEKNUM(A12,2) -> 2 | C12: =MONTH(A12) -> 1 | G12: 11 | H12: =IFERROR(AVERAGE(INDEX(D:D,6+(ROW(A10)-1)*7):INDEX(D:D,12+(ROW(A10)-1)*7)),"") -> 97.158 | I12: =IFERROR(AVERAGE(INDEX(E:E,6+(ROW(B10)-1)*7):INDEX(E:E,12+(ROW(B10)-1)*7)),"") -> 93.722 | J12: =IFERROR(AVERAGE(INDEX(F:F,6+(ROW(C10)-1)*7):INDEX(F:F,12+(ROW(C10)-1)*7)),"") -> 98.516 | K12: Ноябрь | L12: =IFERROR(AVERAGEIF($C:$C,11,D:D),"") | M12: =IFERROR(AVERAGEIF($C:$C,11,E:E),"") | N12: =IFERROR(AVERAGEIF($C:$C,11,F:F),"")
A13: 46034 | B13: =WEEKNUM(A13,2) -> 3 | C13: =MONTH(A13) -> 1 | G13: 12 | H13: =IFERROR(AVERAGE(INDEX(D:D,6+(ROW(A11)-1)*7):INDEX(D:D,12+(ROW(A11)-1)*7)),"") -> 99.64 | I13: =IFERROR(AVERAGE(INDEX(E:E,6+(ROW(B11)-1)*7):INDEX(E:E,12+(ROW(B11)-1)*7)),"") -> 98.335 | J13: =IFERROR(AVERAGE(INDEX(F:F,6+(ROW(C11)-1)*7):INDEX(F:F,12+(ROW(C11)-1)*7)),"") -> 98.47 | K13: Декабрь | L13: =IFERROR(AVERAGEIF($C:$C,12,D:D),"") | M13: =IFERROR(AVERAGEIF($C:$C,12,E:E),"") | N13: =IFERROR(AVERAGEIF($C:$C,12,F:F),"")
A14: 46035 | B14: =WEEKNUM(A14,2) -> 3 | C14: =MONTH(A14) -> 1 | G14: 13 | H14: =IFERROR(AVERAGE(INDEX(D:D,6+(ROW(A12)-1)*7):INDEX(D:D,12+(ROW(A12)-1)*7)),"") | I14: =IFERROR(AVERAGE(INDEX(E:E,6+(ROW(B12)-1)*7):INDEX(E:E,12+(ROW(B12)-1)*7)),"") | J14: =IFERROR(AVERAGE(INDEX(F:F,6+(ROW(C12)-1)*7):INDEX(F:F,12+(ROW(C12)-1)*7)),"") | K14: 2026 | L14: =IFERROR(AVERAGE(L2:L13),"") -> 98.679286 | M14: =IFERROR(AVERAGE(M2:M13),"") -> 93.616429 | N14: =IFERROR(AVERAGE(N2:N13),"") -> 98.6475
A15: 46036 | B15: =WEEKNUM(A15,2) -> 3 | C15: =MONTH(A15) -> 1 | G15: 14 | H15: =IFERROR(AVERAGE(INDEX(D:D,6+(ROW(A13)-1)*7):INDEX(D:D,12+(ROW(A13)-1)*7)),"") | I15: =IFERROR(AVERAGE(INDEX(E:E,6+(ROW(B13)-1)*7):INDEX(E:E,12+(ROW(B13)-1)*7)),"") | J15: =IFERROR(AVERAGE(INDEX(F:F,6+(ROW(C13)-1)*7):INDEX(F:F,12+(ROW(C13)-1)*7)),"")
A16: 46037 | B16: =WEEKNUM(A16,2) -> 3 | C16: =MONTH(A16) -> 1 | G16: 15 | H16: =IFERROR(AVERAGE(INDEX(D:D,6+(ROW(A14)-1)*7):INDEX(D:D,12+(ROW(A14)-1)*7)),"") | I16: =IFERROR(AVERAGE(INDEX(E:E,6+(ROW(B14)-1)*7):INDEX(E:E,12+(ROW(B14)-1)*7)),"") | J16: =IFERROR(AVERAGE(INDEX(F:F,6+(ROW(C14)-1)*7):INDEX(F:F,12+(ROW(C14)-1)*7)),"")
A17: 46038 | B17: =WEEKNUM(A17,2) -> 3 | C17: =MONTH(A17) -> 1 | G17: 16 | H17: =IFERROR(AVERAGE(INDEX(D:D,6+(ROW(A15)-1)*7):INDEX(D:D,12+(ROW(A15)-1)*7)),"") | I17: =IFERROR(AVERAGE(INDEX(E:E,6+(ROW(B15)-1)*7):INDEX(E:E,12+(ROW(B15)-1)*7)),"") | J17: =IFERROR(AVERAGE(INDEX(F:F,6+(ROW(C15)-1)*7):INDEX(F:F,12+(ROW(C15)-1)*7)),"")
A18: 46039 | B18: =WEEKNUM(A18,2) -> 3 | C18: =MONTH(A18) -> 1 | G18: 17 | H18: =IFERROR(AVERAGE(INDEX(D:D,6+(ROW(A16)-1)*7):INDEX(D:D,12+(ROW(A16)-1)*7)),"") | I18: =IFERROR(AVERAGE(INDEX(E:E,6+(ROW(B16)-1)*7):INDEX(E:E,12+(ROW(B16)-1)*7)),"") | J18: =IFERROR(AVERAGE(INDEX(F:F,6+(ROW(C16)-1)*7):INDEX(F:F,12+(ROW(C16)-1)*7)),"")
A19: 46040 | B19: =WEEKNUM(A19,2) -> 3 | C19: =MONTH(A19) -> 1 | G19: 18 | H19: =IFERROR(AVERAGE(INDEX(D:D,6+(ROW(A17)-1)*7):INDEX(D:D,12+(ROW(A17)-1)*7)),"") | I19: =IFERROR(AVERAGE(INDEX(E:E,6+(ROW(B17)-1)*7):INDEX(E:E,12+(ROW(B17)-1)*7)),"") | J19: =IFERROR(AVERAGE(INDEX(F:F,6+(ROW(C17)-1)*7):INDEX(F:F,12+(ROW(C17)-1)*7)),"")
A20: 46041 | B20: =WEEKNUM(A20,2) -> 4 | C20: =MONTH(A20) -> 1 | G20: 19 | H20: =IFERROR(AVERAGE(INDEX(D:D,6+(ROW(A18)-1)*7):INDEX(D:D,12+(ROW(A18)-1)*7)),"") | I20: =IFERROR(AVERAGE(INDEX(E:E,6+(ROW(B18)-1)*7):INDEX(E:E,12+(ROW(B18)-1)*7)),"") | J20: =IFERROR(AVERAGE(INDEX(F:F,6+(ROW(C18)-1)*7):INDEX(F:F,12+(ROW(C18)-1)*7)),"")
A21: 46042 | B21: =WEEKNUM(A21,2) -> 4 | C21: =MONTH(A21) -> 1 | G21: 20 | H21: =IFERROR(AVERAGE(INDEX(D:D,6+(ROW(A19)-1)*7):INDEX(D:D,12+(ROW(A19)-1)*7)),"") | I21: =IFERROR(AVERAGE(INDEX(E:E,6+(ROW(B19)-1)*7):INDEX(E:E,12+(ROW(B19)-1)*7)),"") | J21: =IFERROR(AVERAGE(INDEX(F:F,6+(ROW(C19)-1)*7):INDEX(F:F,12+(ROW(C19)-1)*7)),"")
A22: 46043 | B22: =WEEKNUM(A22,2) -> 4 | C22: =MONTH(A22) -> 1 | G22: 21 | H22: =IFERROR(AVERAGE(INDEX(D:D,6+(ROW(A20)-1)*7):INDEX(D:D,12+(ROW(A20)-1)*7)),"") | I22: =IFERROR(AVERAGE(INDEX(E:E,6+(ROW(B20)-1)*7):INDEX(E:E,12+(ROW(B20)-1)*7)),"") | J22: =IFERROR(AVERAGE(INDEX(F:F,6+(ROW(C20)-1)*7):INDEX(F:F,12+(ROW(C20)-1)*7)),"")
A23: 46044 | B23: =WEEKNUM(A23,2) -> 4 | C23: =MONTH(A23) -> 1 | G23: 22 | H23: =IFERROR(AVERAGE(INDEX(D:D,6+(ROW(A21)-1)*7):INDEX(D:D,12+(ROW(A21)-1)*7)),"") | I23: =IFERROR(AVERAGE(INDEX(E:E,6+(ROW(B21)-1)*7):INDEX(E:E,12+(ROW(B21)-1)*7)),"") | J23: =IFERROR(AVERAGE(INDEX(F:F,6+(ROW(C21)-1)*7):INDEX(F:F,12+(ROW(C21)-1)*7)),"")
A24: 46045 | B24: =WEEKNUM(A24,2) -> 4 | C24: =MONTH(A24) -> 1 | G24: 23 | H24: =IFERROR(AVERAGE(INDEX(D:D,6+(ROW(A22)-1)*7):INDEX(D:D,12+(ROW(A22)-1)*7)),"") | I24: =IFERROR(AVERAGE(INDEX(E:E,6+(ROW(B22)-1)*7):INDEX(E:E,12+(ROW(B22)-1)*7)),"") | J24: =IFERROR(AVERAGE(INDEX(F:F,6+(ROW(C22)-1)*7):INDEX(F:F,12+(ROW(C22)-1)*7)),"")
A25: 46046 | B25: =WEEKNUM(A25,2) -> 4 | C25: =MONTH(A25) -> 1 | G25: 24 | H25: =IFERROR(AVERAGE(INDEX(D:D,6+(ROW(A23)-1)*7):INDEX(D:D,12+(ROW(A23)-1)*7)),"") | I25: =IFERROR(AVERAGE(INDEX(E:E,6+(ROW(B23)-1)*7):INDEX(E:E,12+(ROW(B23)-1)*7)),"") | J25: =IFERROR(AVERAGE(INDEX(F:F,6+(ROW(C23)-1)*7):INDEX(F:F,12+(ROW(C23)-1)*7)),"")
A26: 46047 | B26: =WEEKNUM(A26,2) -> 4 | C26: =MONTH(A26) -> 1 | G26: 25 | H26: =IFERROR(AVERAGE(INDEX(D:D,6+(ROW(A24)-1)*7):INDEX(D:D,12+(ROW(A24)-1)*7)),"") | I26: =IFERROR(AVERAGE(INDEX(E:E,6+(ROW(B24)-1)*7):INDEX(E:E,12+(ROW(B24)-1)*7)),"") | J26: =IFERROR(AVERAGE(INDEX(F:F,6+(ROW(C24)-1)*7):INDEX(F:F,12+(ROW(C24)-1)*7)),"")
... A54: 46075 | B54: =WEEKNUM(A54,2) -> 8 | C54: =MONTH(A54) -> 2 | G54: 53 | H54: =IFERROR(AVERAGE(INDEX(D:D,6+(ROW(A52)-1)*7):INDEX(D:D,12+(ROW(A52)-1)*7)),"") | I54: =IFERROR(AVERAGE(INDEX(E:E,6+(ROW(B52)-1)*7):INDEX(E:E,12+(ROW(B52)-1)*7)),"") | J54: =IFERROR(AVERAGE(INDEX(F:F,6+(ROW(C52)-1)*7):INDEX(F:F,12+(ROW(C52)-1)*7)),"")
A55: 46076 | B55: =WEEKNUM(A55,2) -> 9 | C55: =MONTH(A55) -> 2
A56: 46077 | B56: =WEEKNUM(A56,2) -> 9 | C56: =MONTH(A56) -> 2
A57: 46078 | B57: =WEEKNUM(A57,2) -> 9 | C57: =MONTH(A57) -> 2
A58: 46079 | B58: =WEEKNUM(A58,2) -> 9 | C58: =MONTH(A58) -> 2
A59: 46080 | B59: =WEEKNUM(A59,2) -> 9 | C59: =MONTH(A59) -> 2
A60: 46081 | B60: =WEEKNUM(A60,2) -> 9 | C60: =MONTH(A60) -> 2 | D60: * | E60: * | F60: 99.06
A61: 46082 | B61: =WEEKNUM(A61,2) -> 9 | C61: =MONTH(A61) -> 3
A62: 46083 | B62: =WEEKNUM(A62,2) -> 10 | C62: =MONTH(A62) -> 3 | D62: 99.98 | E62: 90.26 | F62: 98.82
A63: 46084 | B63: =WEEKNUM(A63,2) -> 10 | C63: =MONTH(A63) -> 3 | D63: 98.95 | E63: 78.07 | F63: 98.24
A64: 46085 | B64: =WEEKNUM(A64,2) -> 10 | C64: =MONTH(A64) -> 3 | D64: 99.63 | E64: 82.65 | F64: 98.27
A65: 46086 | B65: =WEEKNUM(A65,2) -> 10 | C65: =MONTH(A65) -> 3 | D65: 99.33 | E65: 98.19 | F65: 95.69
A66: 46087 | B66: =WEEKNUM(A66,2) -> 10 | C66: =MONTH(A66) -> 3 | D66: 99.27 | E66: 99.51 | F66: 97.81
A67: 46088 | B67: =WEEKNUM(A67,2) -> 10 | C67: =MONTH(A67) -> 3
...

Sheet График ТО обоудования
A1: График проведения технического обслуживания оборудования и вспомогательных средст механизации на Январь 2026г. | V1: График проведения технического обслуживания оборудования и вспомогательных средст механизации на Февраль 2026г. | AQ1: График проведения технического обслуживания оборудования и вспомогательных средст механизации на Март 2026г.
A2: Наименование оборудования | B2: 1 неделя | G2: 2 неделя | L2: 3 неделя | Q2: 4 неделя | V2: Наименование оборудования | W2: 1 неделя | AB2: 2 неделя | AG2: 3 неделя | AL2: 4 неделя | AQ2: Наименование оборудования | AR2: 1 неделя | AW2: 2 неделя | BB2: 3 неделя | BG2: 4 неделя
